Workbook

Sheet Summary
A1: 屏幕 RGB 扩展等亮度刺激标定（至刺激值 255）
A2: 本工作簿保持现有 0–20 级标定不变，并依据两次测量的最终平均曲线，分别把 R、G、Gray 延伸到通道值 255；Blue 已在第20级达到255，不再延伸。
A4: 标准亮度步长 (cd/m²) | B4: 1.175 | D4: 现有标定来源 | E4: D:\Chenghang\FineVision\屏幕RGB_0-20等亮度刺激标定.xlsx
A5: 原共同范围 | B5: 0–20级（0–23.5 cd/m²） | D5: 测量平均来源 | E5: D:\Chenghang\Project_33_ShanghaiPostdoc\设备搭建\屏幕\屏幕亮度_两次测量平均与一致性检查.xlsx
A7: 通道 | B7: 最大强度等级 | C7: 新增等级数 | D7: 第20级推荐值 | E7: 末级推荐值 | F7: 255实测亮度 (cd/m²) | G7: 末级目标亮度 (cd/m²) | H7: 末级预计亮度 (cd/m²) | I7: 末级误差 (cd/m²)
A8: R | B8: ='R'!F3 -> 36 | C8: =B8-20 -> 16 | D8: ='R'!D27 -> 178 | E8: ='R'!D43 -> 255 | F8: ='R'!C3 -> 42.25 | G8: ='R'!B43 -> 42.25 | H8: ='R'!H43 -> 42.25 | I8: ='R'!I43 -> 0
A9: G | B9: =G!F3 -> 127 | C9: =B9-20 -> 107 | D9: =G!D27 -> 100 | E9: =G!D134 -> 255 | F9: =G!C3 -> 148.66667 | G9: =G!B134 -> 148.66667 | H9: =G!H134 -> 148.66667 | I9: =G!I134 -> 0
A10: B | B10: =B!F3 -> 20 | C10: =B10-20 -> 0 | D10: =B!D27 -> 255 | E10: =B!D27 -> 255 | F10: =B!C3 -> 23.5 | G10: =B!B27 -> 23.5 | H10: =B!H27 -> 23.5 | I10: =B!I27 -> 0
A11: Gray | B11: =Gray!F3 -> 182 | C11: =B11-20 -> 162 | D11: =Gray!D27 -> 83 | E11: =Gray!D189 -> 255 | F11: =Gray!C3 -> 213.75 | G11: =Gray!B189 -> 213.75 | H11: =Gray!H189 -> 213.75 | I11: =Gray!I189 -> 0
A13: 末级规则：强度等级仍按 1.175 cd/m² 递增；若下一整级超过该通道刺激值255的实测亮度，则末级目标亮度取实测上限，因此最后一步可以小于1.175 cd/m²。
A15: 使用建议：正式实验读取“推荐通道值（整数）”和对应 RGB。若需要严格复现，请同时保留本表中的目标亮度、预计亮度和区段字段。

Sheet R
A1: Red：0–36 扩展等亮度刺激标定
A2: 方法：0–20 级沿用现有标定；21 级以后继续以 1.175 cd/m² 为步长，用两次测量最终平均曲线做分段线性反插值。末级目标亮度截断为刺激值 255 的实测亮度。
A3: 255实测亮度 (cd/m²) | C3: 42.25 | D3: 最大强度等级 | F3: 36 | G3: 标准亮度步长 (cd/m²) | I3: 1.175 | J3: 最大刺激值 | M3: 255
A4: 注意：等级 0 定义为 RGB=(0,0,0)，测量曲线中补入 (输入0, 亮度0)。原 0–20 级的目标亮度、连续反插值、推荐整数 RGB 和预计亮度保持不变；“扩展”行仅用于该通道高于 23.5 cd/m² 的范围。
A6: 强度等级 | B6: 目标亮度 (cd/m²) | C6: 反插值通道值 (连续) | D6: 推荐通道值 (整数) | E6: R | F6: G | G6: B | H6: 预计亮度 (cd/m²) | I6: 亮度误差 (cd/m²) | J6: 相对误差 | K6: 区段 | L6: 实测输入值 | M6: 最终平均亮度 (cd/m²)
A7: 0 | B7: =MIN(A7*$I$3,$C$3) -> 0 | C7: =IF(B7<=0,0,IF(B7>=$C$3,255,INDEX($L$7:$L$23,MATCH(B7,$M$7:$M$23,1))+(B7-INDEX($M$7:$M$23,MATCH(B7,$M$7:$M$23,1)))*(INDEX($L$7:$L$23,MATCH(B7,$M$7:$M$23,1)+1)-INDEX($L$7:$L$23,MATCH(B7,$M$7:$M$23,1)))/(INDEX($M$7:$M$23,MATCH(B7,$M$7:$M$23,1)+1)-INDEX($M$7:$M$23,MATCH(B7,$M$7:$M$23,1))))) -> 0 | D7: =ROUND(C7,0) -> 0 | E7: =D7 -> 0 | F7: =0 -> 0 | G7: =0 -> 0 | H7: =IF(D7<=0,0,IF(D7>=255,$C$3,INDEX($M$7:$M$23,MATCH(D7,$L$7:$L$23,1))+(D7-INDEX($L$7:$L$23,MATCH(D7,$L$7:$L$23,1)))*(INDEX($M$7:$M$23,MATCH(D7,$L$7:$L$23,1)+1)-INDEX($M$7:$M$23,MATCH(D7,$L$7:$L$23,1)))/(INDEX($L$7:$L$23,MATCH(D7,$L$7:$L$23,1)+1)-INDEX($L$7:$L$23,MATCH(D7,$L$7:$L$23,1))))) -> 0 | I7: =H7-B7 -> 0 | J7: =IF(B7=0,0,ABS(I7/B7)) -> 0 | K7: 原0–20 | L7: 0 | M7: 0
A8: 1 | B8: =MIN(A8*$I$3,$C$3) -> 1.175 | C8: =IF(B8<=0,0,IF(B8>=$C$3,255,INDEX($L$7:$L$23,MATCH(B8,$M$7:$M$23,1))+(B8-INDEX($M$7:$M$23,MATCH(B8,$M$7:$M$23,1)))*(INDEX($L$7:$L$23,MATCH(B8,$M$7:$M$23,1)+1)-INDEX($L$7:$L$23,MATCH(B8,$M$7:$M$23,1)))/(INDEX($M$7:$M$23,MATCH(B8,$M$7:$M$23,1)+1)-INDEX($M$7:$M$23,MATCH(B8,$M$7:$M$23,1))))) -> 36.64626 | D8: =ROUND(C8,0) -> 37 | E8: =D8 -> 37 | F8: =0 -> 0 | G8: =0 -> 0 | H8: =IF(D8<=0,0,IF(D8>=255,$C$3,INDEX($M$7:$M$23,MATCH(D8,$L$7:$L$23,1))+(D8-INDEX($L$7:$L$23,MATCH(D8,$L$7:$L$23,1)))*(INDEX($M$7:$M$23,MATCH(D8,$L$7:$L$23,1)+1)-INDEX($M$7:$M$23,MATCH(D8,$L$7:$L$23,1)))/(INDEX($L$7:$L$23,MATCH(D8,$L$7:$L$23,1)+1)-INDEX($L$7:$L$23,MATCH(D8,$L$7:$L$23,1))))) -> 1.1936771 | I8: =H8-B8 -> 0.018677083 | J8: =IF(B8=0,0,ABS(I8/B8)) -> 0.01589539 | K8: 原0–20 | L8: 15 | M8: 0.35288333
A9: 2 | B9: =MIN(A9*$I$3,$C$3) -> 2.35 | C9: =IF(B9<=0,0,IF(B9>=$C$3,255,INDEX($L$7:$L$23,MATCH(B9,$M$7:$M$23,1))+(B9-INDEX($M$7:$M$23,MATCH(B9,$M$7:$M$23,1)))*(INDEX($L$7:$L$23,MATCH(B9,$M$7:$M$23,1)+1)-INDEX($L$7:$L$23,MATCH(B9,$M$7:$M$23,1)))/(INDEX($M$7:$M$23,MATCH(B9,$M$7:$M$23,1)+1)-INDEX($M$7:$M$23,MATCH(B9,$M$7:$M$23,1))))) -> 54.116564 | D9: =ROUND(C9,0) -> 54 | E9: =D9 -> 54 | F9: =0 -> 0 | G9: =0 -> 0 | H9: =IF(D9<=0,0,IF(D9>=255,$C$3,INDEX($M$7:$M$23,MATCH(D9,$L$7:$L$23,1))+(D9-INDEX($L$7:$L$23,MATCH(D9,$L$7:$L$23,1)))*(INDEX($M$7:$M$23,MATCH(D9,$L$7:$L$23,1)+1)-INDEX($M$7:$M$23,MATCH(D9,$L$7:$L$23,1)))/(INDEX($L$7:$L$23,MATCH(D9,$L$7:$L$23,1)+1)-INDEX($L$7:$L$23,MATCH(D9,$L$7:$L$23,1))))) -> 2.3397083 | I9: =H9-B9 -> -0.010291667 | J9: =IF(B9=0,0,ABS(I9/B9)) -> 0.0043794326 | K9: 原0–20 | L9: 31 | M9: 0.87688333
A10: 3 | B10: =MIN(A10*$I$3,$C$3) -> 3.525 | C10: =IF(B10<=0,0,IF(B10>=$C$3,255,INDEX($L$7:$L$23,MATCH(B10,$M$7:$M$23,1))+(B10-INDEX($M$7:$M$23,MATCH(B10,$M$7:$M$23,1)))*(INDEX($L$7:$L$23,MATCH(B10,$M$7:$M$23,1)+1)-INDEX($L$7:$L$23,MATCH(B10,$M$7:$M$23,1)))/(INDEX($M$7:$M$23,MATCH(B10,$M$7:$M$23,1)+1)-INDEX($M$7:$M$23,MATCH(B10,$M$7:$M$23,1))))) -> 67.32024 | D10: =ROUND(C10,0) -> 67 | E10: =D10 -> 67 | F10: =0 -> 0 | G10: =0 -> 0 | H10: =IF(D10<=0,0,IF(D10>=255,$C$3,INDEX($M$7:$M$23,MATCH(D10,$L$7:$L$23,1))+(D10-INDEX($L$7:$L$23,MATCH(D10,$L$7:$L$23,1)))*(INDEX($M$7:$M$23,MATCH(D10,$L$7:$L$23,1)+1)-INDEX($M$7:$M$23,MATCH(D10,$L$7:$L$23,1)))/(INDEX($L$7:$L$23,MATCH(D10,$L$7:$L$23,1)+1)-INDEX($L$7:$L$23,MATCH(D10,$L$7:$L$23,1))))) -> 3.4960417 | I10: =H10-B10 -> -0.028958333 | J10: =IF(B10=0,0,ABS(I10/B10)) -> 0.00821513 | K10: 原0–20 | L10: 47 | M10: 1.7216667
A11: 4 | B11: =MIN(A11*$I$3,$C$3) -> 4.7 | C11: =IF(B11<=0,0,IF(B11>=$C$3,255,INDEX($L$7:$L$23,MATCH(B11,$M$7:$M$23,1))+(B11-INDEX($M$7:$M$23,MATCH(B11,$M$7:$M$23,1)))*(INDEX($L$7:$L$23,MATCH(B11,$M$7:$M$23,1)+1)-INDEX($L$7:$L$23,MATCH(B11,$M$7:$M$23,1)))/(INDEX($M$7:$M$23,MATCH(B11,$M$7:$M$23,1)+1)-INDEX($M$7:$M$23,MATCH(B11,$M$7:$M$23,1))))) -> 79.772481 | D11: =ROUND(C11,0) -> 80 | E11: =D11 -> 80 | F11: =0 -> 0 | G11: =0 -> 0 | H11: =IF(D11<=0,0,IF(D11>=255,$C$3,INDEX($M$7:$M$23,MATCH(D11,$L$7:$L$23,1))+(D11-INDEX($L$7:$L$23,MATCH(D11,$L$7:$L$23,1)))*(INDEX($M$7:$M$23,MATCH(D11,$L$7:$L$23,1)+1)-INDEX($M$7:$M$23,MATCH(D11,$L$7:$L$23,1)))/(INDEX($L$7:$L$23,MATCH(D11,$L$7:$L$23,1)+1)-INDEX($L$7:$L$23,MATCH(D11,$L$7:$L$23,1))))) -> 4.735 | I11: =H11-B11 -> 0.035 | J11: =IF(B11=0,0,ABS(I11/B11)) -> 0.0074468085 | K11: 原0–20 | L11: 63 | M11: 3.1343333
A12: 5 | B12: =MIN(A12*$I$3,$C$3) -> 5.875 | C12: =IF(B12<=0,0,IF(B12>=$C$3,255,INDEX($L$7:$L$23,MATCH(B12,$M$7:$M$23,1))+(B12-INDEX($M$7:$M$23,MATCH(B12,$M$7:$M$23,1)))*(INDEX($L$7:$L$23,MATCH(B12,$M$7:$M$23,1)+1)-INDEX($L$7:$L$23,MATCH(B12,$M$7:$M$23,1)))/(INDEX($M$7:$M$23,MATCH(B12,$M$7:$M$23,1)+1)-INDEX($M$7:$M$23,MATCH(B12,$M$7:$M$23,1))))) -> 87.410618 | D12: =ROUND(C12,0) -> 87 | E12: =D12 -> 87 | F12: =0 -> 0 | G12: =0 -> 0 | H12: =IF(D12<=0,0,IF(D12>=255,$C$3,INDEX($M$7:$M$23,MATCH(D12,$L$7:$L$23,1))+(D12-INDEX($L$7:$L$23,MATCH(D12,$L$7:$L$23,1)))*(INDEX($M$7:$M$23,MATCH(D12,$L$7:$L$23,1)+1)-INDEX($M$7:$M$23,MATCH(D12,$L$7:$L$23,1)))/(INDEX($L$7:$L$23,MATCH(D12,$L$7:$L$23,1)+1)-INDEX($L$7:$L$23,MATCH(D12,$L$7:$L$23,1))))) -> 5.8118333 | I12: =H12-B12 -> -0.063166667 | J12: =IF(B12=0,0,ABS(I12/B12)) -> 0.010751773 | K12: 原0–20 | L12: 79 | M12: 4.5811667
A13: 6 | B13: =MIN(A13*$I$3,$C$3) -> 7.05 | C13: =IF(B13<=0,0,IF(B13>=$C$3,255,INDEX($L$7:$L$23,MATCH(B13,$M$7:$M$23,1))+(B13-INDEX($M$7:$M$23,MATCH(B13,$M$7:$M$23,1)))*(INDEX($L$7:$L$23,MATCH(B13,$M$7:$M$23,1)+1)-INDEX($L$7:$L$23,MATCH(B13,$M$7:$M$23,1)))/(INDEX($M$7:$M$23,MATCH(B13,$M$7:$M$23,1)+1)-INDEX($M$7:$M$23,MATCH(B13,$M$7:$M$23,1))))) -> 95.062365 | D13: =ROUND(C13,0) -> 95 | E13: =D13 -> 95 | F13: =0 -> 0 | G13: =0 -> 0 | H13: =IF(D13<=0,0,IF(D13>=255,$C$3,INDEX($M$7:$M$23,MATCH(D13,$L$7:$L$23,1))+(D13-INDEX($L$7:$L$23,MATCH(D13,$L$7:$L$23,1)))*(INDEX($M$7:$M$23,MATCH(D13,$L$7:$L$23,1)+1)-INDEX($M$7:$M$23,MATCH(D13,$L$7:$L$23,1)))/(INDEX($L$7:$L$23,MATCH(D13,$L$7:$L$23,1)+1)-INDEX($L$7:$L$23,MATCH(D13,$L$7:$L$23,1))))) -> 7.0425 | I13: =H13-B13 -> -0.0075 | J13: =IF(B13=0,0,ABS(I13/B13)) -> 0.0010638298 | K13: 原0–20 | L13: 95 | M13: 7.0425
A14: 7 | B14: =MIN(A14*$I$3,$C$3) -> 8.225 | C14: =IF(B14<=0,0,IF(B14>=$C$3,255,INDEX($L$7:$L$23,MATCH(B14,$M$7:$M$23,1))+(B14-INDEX($M$7:$M$23,MATCH(B14,$M$7:$M$23,1)))*(INDEX($L$7:$L$23,MATCH(B14,$M$7:$M$23,1)+1)-INDEX($L$7:$L$23,MATCH(B14,$M$7:$M$23,1)))/(INDEX($M$7:$M$23,MATCH(B14,$M$7:$M$23,1)+1)-INDEX($M$7:$M$23,MATCH(B14,$M$7:$M$23,1))))) -> 104.83283 | D14: =ROUND(C14,0) -> 105 | E14: =D14 -> 105 | F14: =0 -> 0 | G14: =0 -> 0 | H14: =IF(D14<=0,0,IF(D14>=255,$C$3,INDEX($M$7:$M$23,MATCH(D14,$L$7:$L$23,1))+(D14-INDEX($L$7:$L$23,MATCH(D14,$L$7:$L$23,1)))*(INDEX($M$7:$M$23,MATCH(D14,$L$7:$L$23,1)+1)-INDEX($M$7:$M$23,MATCH(D14,$L$7:$L$23,1)))/(INDEX($L$7:$L$23,MATCH(D14,$L$7:$L$23,1)+1)-INDEX($L$7:$L$23,MATCH(D14,$L$7:$L$23,1))))) -> 8.2451042 | I14: =H14-B14 -> 0.020104167 | J14: =IF(B14=0,0,ABS(I14/B14)) -> 0.0024442756 | K14: 原0–20 | L14: 111 | M14: 8.9666667
A15: 8 | B15: =MIN(A15*$I$3,$C$3) -> 9.4 | C15: =IF(B15<=0,0,IF(B15>=$C$3,255,INDEX($L$7:$L$23,MATCH(B15,$M$7:$M$23,1))+(B15-INDEX($M$7:$M$23,MATCH(B15,$M$7:$M$23,1)))*(INDEX($L$7:$L$23,MATCH(B15,$M$7:$M$23,1)+1)-INDEX($L$7:$L$23,MATCH(B15,$M$7:$M$23,1)))/(INDEX($M$7:$M$23,MATCH(B15,$M$7:$M$23,1)+1)-INDEX($M$7:$M$23,MATCH(B15,$M$7:$M$23,1))))) -> 113.57745 | D15: =ROUND(C15,0) -> 114 | E15: =D15 -> 114 | F15: =0 -> 0 | G15: =0 -> 0 | H15: =IF(D15<=0,0,IF(D15>=255,$C$3,INDEX($M$7:$M$23,MATCH(D15,$L$7:$L$23,1))+(D15-INDEX($L$7:$L$23,MATCH(D15,$L$7:$L$23,1)))*(INDEX($M$7:$M$23,MATCH(D15,$L$7:$L$23,1)+1)-INDEX($M$7:$M$23,MATCH(D15,$L$7:$L$23,1)))/(INDEX($L$7:$L$23,MATCH(D15,$L$7:$L$23,1)+1)-INDEX($L$7:$L$23,MATCH(D15,$L$7:$L$23,1))))) -> 9.4710417 | I15: =H15-B15 -> 0.071041667 | J15: =IF(B15=0,0,ABS(I15/B15)) -> 0.0075576241 | K15: 原0–20 | L15: 127 | M15: 11.656667
A16: 9 | B16: =MIN(A16*$I$3,$C$3) -> 10.575 | C16: =IF(B16<=0,0,IF(B16>=$C$3,255,INDEX($L$7:$L$23,MATCH(B16,$M$7:$M$23,1))+(B16-INDEX($M$7:$M$23,MATCH(B16,$M$7:$M$23,1)))*(INDEX($L$7:$L$23,MATCH(B16,$M$7:$M$23,1)+1)-INDEX($L$7:$L$23,MATCH(B16,$M$7:$M$23,1)))/(INDEX($M$7:$M$23,MATCH(B16,$M$7:$M$23,1)+1)-INDEX($M$7:$M$23,MATCH(B16,$M$7:$M$23,1))))) -> 120.56629 | D16: =ROUND(C16,0) -> 121 | E16: =D16 -> 121 | F16: =0 -> 0 | G16: =0 -> 0 | H16: =IF(D16<=0,0,IF(D16>=255,$C$3,INDEX($M$7:$M$23,MATCH(D16,$L$7:$L$23,1))+(D16-INDEX($L$7:$L$23,MATCH(D16,$L$7:$L$23,1)))*(INDEX($M$7:$M$23,MATCH(D16,$L$7:$L$23,1)+1)-INDEX($M$7:$M$23,MATCH(D16,$L$7:$L$23,1)))/(INDEX($L$7:$L$23,MATCH(D16,$L$7:$L$23,1)+1)-INDEX($L$7:$L$23,MATCH(D16,$L$7:$L$23,1))))) -> 10.647917 | I16: =H16-B16 -> 0.072916667 | J16: =IF(B16=0,0,ABS(I16/B16)) -> 0.0068951931 | K16: 原0–20 | L16: 143 | M16: 15.411667
A17: 10 | B17: =MIN(A17*$I$3,$C$3) -> 11.75 | C17: =IF(B17<=0,0,IF(B17>=$C$3,255,INDEX($L$7:$L$23,MATCH(B17,$M$7:$M$23,1))+(B17-INDEX($M$7:$M$23,MATCH(B17,$M$7:$M$23,1)))*(INDEX($L$7:$L$23,MATCH(B17,$M$7:$M$23,1)+1)-INDEX($L$7:$L$23,MATCH(B17,$M$7:$M$23,1)))/(INDEX($M$7:$M$23,MATCH(B17,$M$7:$M$23,1)+1)-INDEX($M$7:$M$23,MATCH(B17,$M$7:$M$23,1))))) -> 127.39769 | D17: =ROUND(C17,0) -> 127 | E17: =D17 -> 127 | F17: =0 -> 0 | G17: =0 -> 0 | H17: =IF(D17<=0,0,IF(D17>=255,$C$3,INDEX($M$7:$M$23,MATCH(D17,$L$7:$L$23,1))+(D17-INDEX($L$7:$L$23,MATCH(D17,$L$7:$L$23,1)))*(INDEX($M$7:$M$23,MATCH(D17,$L$7:$L$23,1)+1)-INDEX($M$7:$M$23,MATCH(D17,$L$7:$L$23,1)))/(INDEX($L$7:$L$23,MATCH(D17,$L$7:$L$23,1)+1)-INDEX($L$7:$L$23,MATCH(D17,$L$7:$L$23,1))))) -> 11.656667 | I17: =H17-B17 -> -0.093333333 | J17: =IF(B17=0,0,ABS(I17/B17)) -> 0.0079432624 | K17: 原0–20 | L17: 159 | M17: 18.336667
A18: 11 | B18: =MIN(A18*$I$3,$C$3) -> 12.925 | C18: =IF(B18<=0,0,IF(B18>=$C$3,255,INDEX($L$7:$L$23,MATCH(B18,$M$7:$M$23,1))+(B18-INDEX($M$7:$M$23,MATCH(B18,$M$7:$M$23,1)))*(INDEX($L$7:$L$23,MATCH(B18,$M$7:$M$23,1)+1)-INDEX($L$7:$L$23,MATCH(B18,$M$7:$M$23,1)))/(INDEX($M$7:$M$23,MATCH(B18,$M$7:$M$23,1)+1)-INDEX($M$7:$M$23,MATCH(B18,$M$7:$M$23,1))))) -> 132.40435 | D18: =ROUND(C18,0) -> 132 | E18: =D18 -> 132 | F18: =0 -> 0 | G18: =0 -> 0 | H18: =IF(D18<=0,0,IF(D18>=255,$C$3,INDEX($M$7:$M$23,MATCH(D18,$L$7:$L$23,1))+(D18-INDEX($L$7:$L$23,MATCH(D18,$L$7:$L$23,1)))*(INDEX($M$7:$M$23,MATCH(D18,$L$7:$L$23,1)+1)-INDEX($M$7:$M$23,MATCH(D18,$L$7:$L$23,1)))/(INDEX($L$7:$L$23,MATCH(D18,$L$7:$L$23,1)+1)-INDEX($L$7:$L$23,MATCH(D18,$L$7:$L$23,1))))) -> 12.830104 | I18: =H18-B18 -> -0.094895833 | J18: =IF(B18=0,0,ABS(I18/B18)) -> 0.0073420374 | K18: 原0–20 | L18: 175 | M18: 22.545
... A23: 16 | B23: =MIN(A23*$I$3,$C$3) -> 18.8 | C23: =IF(B23<=0,0,IF(B23>=$C$3,255,INDEX($L$7:$L$23,MATCH(B23,$M$7:$M$23,1))+(B23-INDEX($M$7:$M$23,MATCH(B23,$M$7:$M$23,1)))*(INDEX($L$7:$L$23,MATCH(B23,$M$7:$M$23,1)+1)-INDEX($L$7:$L$23,MATCH(B23,$M$7:$M$23,1)))/(INDEX($M$7:$M$23,MATCH(B23,$M$7:$M$23,1)+1)-INDEX($M$7:$M$23,MATCH(B23,$M$7:$M$23,1))))) -> 160.76158 | D23: =ROUND(C23,0) -> 161 | E23: =D23 -> 161 | F23: =0 -> 0 | G23: =0 -> 0 | H23: =IF(D23<=0,0,IF(D23>=255,$C$3,INDEX($M$7:$M$23,MATCH(D23,$L$7:$L$23,1))+(D23-INDEX($L$7:$L$23,MATCH(D23,$L$7:$L$23,1)))*(INDEX($M$7:$M$23,MATCH(D23,$L$7:$L$23,1)+1)-INDEX($M$7:$M$23,MATCH(D23,$L$7:$L$23,1)))/(INDEX($L$7:$L$23,MATCH(D23,$L$7:$L$23,1)+1)-INDEX($L$7:$L$23,MATCH(D23,$L$7:$L$23,1))))) -> 18.862708 | I23: =H23-B23 -> 0.062708333 | J23: =IF(B23=0,0,ABS(I23/B23)) -> 0.0033355496 | K23: 原0–20 | L23: 255 | M23: 42.25
A24: 17 | B24: =MIN(A24*$I$3,$C$3) -> 19.975 | C24: =IF(B24<=0,0,IF(B24>=$C$3,255,INDEX($L$7:$L$23,MATCH(B24,$M$7:$M$23,1))+(B24-INDEX($M$7:$M$23,MATCH(B24,$M$7:$M$23,1)))*(INDEX($L$7:$L$23,MATCH(B24,$M$7:$M$23,1)+1)-INDEX($L$7:$L$23,MATCH(B24,$M$7:$M$23,1)))/(INDEX($M$7:$M$23,MATCH(B24,$M$7:$M$23,1)+1)-INDEX($M$7:$M$23,MATCH(B24,$M$7:$M$23,1))))) -> 165.22891 | D24: =ROUND(C24,0) -> 165 | E24: =D24 -> 165 | F24: =0 -> 0 | G24: =0 -> 0 | H24: =IF(D24<=0,0,IF(D24>=255,$C$3,INDEX($M$7:$M$23,MATCH(D24,$L$7:$L$23,1))+(D24-INDEX($L$7:$L$23,MATCH(D24,$L$7:$L$23,1)))*(INDEX($M$7:$M$23,MATCH(D24,$L$7:$L$23,1)+1)-INDEX($M$7:$M$23,MATCH(D24,$L$7:$L$23,1)))/(INDEX($L$7:$L$23,MATCH(D24,$L$7:$L$23,1)+1)-INDEX($L$7:$L$23,MATCH(D24,$L$7:$L$23,1))))) -> 19.914792 | I24: =H24-B24 -> -0.060208333 | J24: =IF(B24=0,0,ABS(I24/B24)) -> 0.0030141844 | K24: 原0–20
A25: 18 | B25: =MIN(A25*$I$3,$C$3) -> 21.15 | C25: =IF(B25<=0,0,IF(B25>=$C$3,255,INDEX($L$7:$L$23,MATCH(B25,$M$7:$M$23,1))+(B25-INDEX($M$7:$M$23,MATCH(B25,$M$7:$M$23,1)))*(INDEX($L$7:$L$23,MATCH(B25,$M$7:$M$23,1)+1)-INDEX($L$7:$L$23,MATCH(B25,$M$7:$M$23,1)))/(INDEX($M$7:$M$23,MATCH(B25,$M$7:$M$23,1)+1)-INDEX($M$7:$M$23,MATCH(B25,$M$7:$M$23,1))))) -> 169.69624 | D25: =ROUND(C25,0) -> 170 | E25: =D25 -> 170 | F25: =0 -> 0 | G25: =0 -> 0 | H25: =IF(D25<=0,0,IF(D25>=255,$C$3,INDEX($M$7:$M$23,MATCH(D25,$L$7:$L$23,1))+(D25-INDEX($L$7:$L$23,MATCH(D25,$L$7:$L$23,1)))*(INDEX($M$7:$M$23,MATCH(D25,$L$7:$L$23,1)+1)-INDEX($M$7:$M$23,MATCH(D25,$L$7:$L$23,1)))/(INDEX($L$7:$L$23,MATCH(D25,$L$7:$L$23,1)+1)-INDEX($L$7:$L$23,MATCH(D25,$L$7:$L$23,1))))) -> 21.229896 | I25: =H25-B25 -> 0.079895833 | J25: =IF(B25=0,0,ABS(I25/B25)) -> 0.0037775808 | K25: 原0–20
A26: 19 | B26: =MIN(A26*$I$3,$C$3) -> 22.325 | C26: =IF(B26<=0,0,IF(B26>=$C$3,255,INDEX($L$7:$L$23,MATCH(B26,$M$7:$M$23,1))+(B26-INDEX($M$7:$M$23,MATCH(B26,$M$7:$M$23,1)))*(INDEX($L$7:$L$23,MATCH(B26,$M$7:$M$23,1)+1)-INDEX($L$7:$L$23,MATCH(B26,$M$7:$M$23,1)))/(INDEX($M$7:$M$23,MATCH(B26,$M$7:$M$23,1)+1)-INDEX($M$7:$M$23,MATCH(B26,$M$7:$M$23,1))))) -> 174.16356 | D26: =ROUND(C26,0) -> 174 | E26: =D26 -> 174 | F26: =0 -> 0 | G26: =0 -> 0 | H26: =IF(D26<=0,0,IF(D26>=255,$C$3,INDEX($M$7:$M$23,MATCH(D26,$L$7:$L$23,1))+(D26-INDEX($L$7:$L$23,MATCH(D26,$L$7:$L$23,1)))*(INDEX($M$7:$M$23,MATCH(D26,$L$7:$L$23,1)+1)-INDEX($M$7:$M$23,MATCH(D26,$L$7:$L$23,1)))/(INDEX($L$7:$L$23,MATCH(D26,$L$7:$L$23,1)+1)-INDEX($L$7:$L$23,MATCH(D26,$L$7:$L$23,1))))) -> 22.281979 | I26: =H26-B26 -> -0.043020833 | J26: =IF(B26=0,0,ABS(I26/B26)) -> 0.001927025 | K26: 原0–20
A27: 20 | B27: =MIN(A27*$I$3,$C$3) -> 23.5 | C27: =IF(B27<=0,0,IF(B27>=$C$3,255,INDEX($L$7:$L$23,MATCH(B27,$M$7:$M$23,1))+(B27-INDEX($M$7:$M$23,MATCH(B27,$M$7:$M$23,1)))*(INDEX($L$7:$L$23,MATCH(B27,$M$7:$M$23,1)+1)-INDEX($L$7:$L$23,MATCH(B27,$M$7:$M$23,1)))/(INDEX($M$7:$M$23,MATCH(B27,$M$7:$M$23,1)+1)-INDEX($M$7:$M$23,MATCH(B27,$M$7:$M$23,1))))) -> 178.11837 | D27: =ROUND(C27,0) -> 178 | E27: =D27 -> 178 | F27: =0 -> 0 | G27: =0 -> 0 | H27: =IF(D27<=0,0,IF(D27>=255,$C$3,INDEX($M$7:$M$23,MATCH(D27,$L$7:$L$23,1))+(D27-INDEX($L$7:$L$23,MATCH(D27,$L$7:$L$23,1)))*(INDEX($M$7:$M$23,MATCH(D27,$L$7:$L$23,1)+1)-INDEX($M$7:$M$23,MATCH(D27,$L$7:$L$23,1)))/(INDEX($L$7:$L$23,MATCH(D27,$L$7:$L$23,1)+1)-INDEX($L$7:$L$23,MATCH(D27,$L$7:$L$23,1))))) -> 23.46375 | I27: =H27-B27 -> -0.03625 | J27: =IF(B27=0,0,ABS(I27/B27)) -> 0.0015425532 | K27: 原0–20
A28: 21 | B28: =MIN(A28*$I$3,$C$3) -> 24.675 | C28: =IF(B28<=0,0,IF(B28>=$C$3,255,INDEX($L$7:$L$23,MATCH(B28,$M$7:$M$23,1))+(B28-INDEX($M$7:$M$23,MATCH(B28,$M$7:$M$23,1)))*(INDEX($L$7:$L$23,MATCH(B28,$M$7:$M$23,1)+1)-INDEX($L$7:$L$23,MATCH(B28,$M$7:$M$23,1)))/(INDEX($M$7:$M$23,MATCH(B28,$M$7:$M$23,1)+1)-INDEX($M$7:$M$23,MATCH(B28,$M$7:$M$23,1))))) -> 181.9551 | D28: =ROUND(C28,0) -> 182 | E28: =D28 -> 182 | F28: =0 -> 0 | G28: =0 -> 0 | H28: =IF(D28<=0,0,IF(D28>=255,$C$3,INDEX($M$7:$M$23,MATCH(D28,$L$7:$L$23,1))+(D28-INDEX($L$7:$L$23,MATCH(D28,$L$7:$L$23,1)))*(INDEX($M$7:$M$23,MATCH(D28,$L$7:$L$23,1)+1)-INDEX($M$7:$M$23,MATCH(D28,$L$7:$L$23,1)))/(INDEX($L$7:$L$23,MATCH(D28,$L$7:$L$23,1)+1)-INDEX($L$7:$L$23,MATCH(D28,$L$7:$L$23,1))))) -> 24.68875 | I28: =H28-B28 -> 0.01375 | J28: =IF(B28=0,0,ABS(I28/B28)) -> 0.00055724417 | K28: 扩展
A29: 22 | B29: =MIN(A29*$I$3,$C$3) -> 25.85 | C29: =IF(B29<=0,0,IF(B29>=$C$3,255,INDEX($L$7:$L$23,MATCH(B29,$M$7:$M$23,1))+(B29-INDEX($M$7:$M$23,MATCH(B29,$M$7:$M$23,1)))*(INDEX($L$7:$L$23,MATCH(B29,$M$7:$M$23,1)+1)-INDEX($L$7:$L$23,MATCH(B29,$M$7:$M$23,1)))/(INDEX($M$7:$M$23,MATCH(B29,$M$7:$M$23,1)+1)-INDEX($M$7:$M$23,MATCH(B29,$M$7:$M$23,1))))) -> 185.79184 | D29: =ROUND(C29,0) -> 186 | E29: =D29 -> 186 | F29: =0 -> 0 | G29: =0 -> 0 | H29: =IF(D29<=0,0,IF(D29>=255,$C$3,INDEX($M$7:$M$23,MATCH(D29,$L$7:$L$23,1))+(D29-INDEX($L$7:$L$23,MATCH(D29,$L$7:$L$23,1)))*(INDEX($M$7:$M$23,MATCH(D29,$L$7:$L$23,1)+1)-INDEX($M$7:$M$23,MATCH(D29,$L$7:$L$23,1)))/(INDEX($L$7:$L$23,MATCH(D29,$L$7:$L$23,1)+1)-INDEX($L$7:$L$23,MATCH(D29,$L$7:$L$23,1))))) -> 25.91375 | I29: =H29-B29 -> 0.06375 | J29: =IF(B29=0,0,ABS(I29/B29)) -> 0.0024661509 | K29: 扩展
A30: 23 | B30: =MIN(A30*$I$3,$C$3) -> 27.025 | C30: =IF(B30<=0,0,IF(B30>=$C$3,255,INDEX($L$7:$L$23,MATCH(B30,$M$7:$M$23,1))+(B30-INDEX($M$7:$M$23,MATCH(B30,$M$7:$M$23,1)))*(INDEX($L$7:$L$23,MATCH(B30,$M$7:$M$23,1)+1)-INDEX($L$7:$L$23,MATCH(B30,$M$7:$M$23,1)))/(INDEX($M$7:$M$23,MATCH(B30,$M$7:$M$23,1)+1)-INDEX($M$7:$M$23,MATCH(B30,$M$7:$M$23,1))))) -> 189.62857 | D30: =ROUND(C30,0) -> 190 | E30: =D30 -> 190 | F30: =0 -> 0 | G30: =0 -> 0 | H30: =IF(D30<=0,0,IF(D30>=255,$C$3,INDEX($M$7:$M$23,MATCH(D30,$L$7:$L$23,1))+(D30-INDEX($L$7:$L$23,MATCH(D30,$L$7:$L$23,1)))*(INDEX($M$7:$M$23,MATCH(D30,$L$7:$L$23,1)+1)-INDEX($M$7:$M$23,MATCH(D30,$L$7:$L$23,1)))/(INDEX($L$7:$L$23,MATCH(D30,$L$7:$L$23,1)+1)-INDEX($L$7:$L$23,MATCH(D30,$L$7:$L$23,1))))) -> 27.13875 | I30: =H30-B30 -> 0.11375 | J30: =IF(B30=0,0,ABS(I30/B30)) -> 0.0042090657 | K30: 扩展
A31: 24 | B31: =MIN(A31*$I$3,$C$3) -> 28.2 | C31: =IF(B31<=0,0,IF(B31>=$C$3,255,INDEX($L$7:$L$23,MATCH(B31,$M$7:$M$23,1))+(B31-INDEX($M$7:$M$23,MATCH(B31,$M$7:$M$23,1)))*(INDEX($L$7:$L$23,MATCH(B31,$M$7:$M$23,1)+1)-INDEX($L$7:$L$23,MATCH(B31,$M$7:$M$23,1)))/(INDEX($M$7:$M$23,MATCH(B31,$M$7:$M$23,1)+1)-INDEX($M$7:$M$23,MATCH(B31,$M$7:$M$23,1))))) -> 194.4221 | D31: =ROUND(C31,0) -> 194 | E31: =D31 -> 194 | F31: =0 -> 0 | G31: =0 -> 0 | H31: =IF(D31<=0,0,IF(D31>=255,$C$3,INDEX($M$7:$M$23,MATCH(D31,$L$7:$L$23,1))+(D31-INDEX($L$7:$L$23,MATCH(D31,$L$7:$L$23,1)))*(INDEX($M$7:$M$23,MATCH(D31,$L$7:$L$23,1)+1)-INDEX($M$7:$M$23,MATCH(D31,$L$7:$L$23,1)))/(INDEX($L$7:$L$23,MATCH(D31,$L$7:$L$23,1)+1)-INDEX($L$7:$L$23,MATCH(D31,$L$7:$L$23,1))))) -> 28.106875 | I31: =H31-B31 -> -0.093125 | J31: =IF(B31=0,0,ABS(I31/B31)) -> 0.003302305 | K31: 扩展
A32: 25 | B32: =MIN(A32*$I$3,$C$3) -> 29.375 | C32: =IF(B32<=0,0,IF(B32>=$C$3,255,INDEX($L$7:$L$23,MATCH(B32,$M$7:$M$23,1))+(B32-INDEX($M$7:$M$23,MATCH(B32,$M$7:$M$23,1)))*(INDEX($L$7:$L$23,MATCH(B32,$M$7:$M$23,1)+1)-INDEX($L$7:$L$23,MATCH(B32,$M$7:$M$23,1)))/(INDEX($M$7:$M$23,MATCH(B32,$M$7:$M$23,1)+1)-INDEX($M$7:$M$23,MATCH(B32,$M$7:$M$23,1))))) -> 199.74788 | D32: =ROUND(C32,0) -> 200 | E32: =D32 -> 200 | F32: =0 -> 0 | G32: =0 -> 0 | H32: =IF(D32<=0,0,IF(D32>=255,$C$3,INDEX($M$7:$M$23,MATCH(D32,$L$7:$L$23,1))+(D32-INDEX($L$7:$L$23,MATCH(D32,$L$7:$L$23,1)))*(INDEX($M$7:$M$23,MATCH(D32,$L$7:$L$23,1)+1)-INDEX($M$7:$M$23,MATCH(D32,$L$7:$L$23,1)))/(INDEX($L$7:$L$23,MATCH(D32,$L$7:$L$23,1)+1)-INDEX($L$7:$L$23,MATCH(D32,$L$7:$L$23,1))))) -> 29.430625 | I32: =H32-B32 -> 0.055625 | J32: =IF(B32=0,0,ABS(I32/B32)) -> 0.001893617 | K32: 扩展
A33: 26 | B33: =MIN(A33*$I$3,$C$3) -> 30.55 | C33: =IF(B33<=0,0,IF(B33>=$C$3,255,INDEX($L$7:$L$23,MATCH(B33,$M$7:$M$23,1))+(B33-INDEX($M$7:$M$23,MATCH(B33,$M$7:$M$23,1)))*(INDEX($L$7:$L$23,MATCH(B33,$M$7:$M$23,1)+1)-INDEX($L$7:$L$23,MATCH(B33,$M$7:$M$23,1)))/(INDEX($M$7:$M$23,MATCH(B33,$M$7:$M$23,1)+1)-INDEX($M$7:$M$23,MATCH(B33,$M$7:$M$23,1))))) -> 205.07365 | D33: =ROUND(C33,0) -> 205 | E33: =D33 -> 205 | F33: =0 -> 0 | G33: =0 -> 0 | H33: =IF(D33<=0,0,IF(D33>=255,$C$3,INDEX($M$7:$M$23,MATCH(D33,$L$7:$L$23,1))+(D33-INDEX($L$7:$L$23,MATCH(D33,$L$7:$L$23,1)))*(INDEX($M$7:$M$23,MATCH(D33,$L$7:$L$23,1)+1)-INDEX($M$7:$M$23,MATCH(D33,$L$7:$L$23,1)))/(INDEX($L$7:$L$23,MATCH(D33,$L$7:$L$23,1)+1)-INDEX($L$7:$L$23,MATCH(D33,$L$7:$L$23,1))))) -> 30.53375 | I33: =H33-B33 -> -0.01625 | J33: =IF(B33=0,0,ABS(I33/B33)) -> 0.00053191489 | K33: 扩展
A34: 27 | B34: =MIN(A34*$I$3,$C$3) -> 31.725 | C34: =IF(B34<=0,0,IF(B34>=$C$3,255,INDEX($L$7:$L$23,MATCH(B34,$M$7:$M$23,1))+(B34-INDEX($M$7:$M$23,MATCH(B34,$M$7:$M$23,1)))*(INDEX($L$7:$L$23,MATCH(B34,$M$7:$M$23,1)+1)-INDEX($L$7:$L$23,MATCH(B34,$M$7:$M$23,1)))/(INDEX($M$7:$M$23,MATCH(B34,$M$7:$M$23,1)+1)-INDEX($M$7:$M$23,MATCH(B34,$M$7:$M$23,1))))) -> 209.7618 | D34: =ROUND(C34,0) -> 210 | E34: =D34 -> 210 | F34: =0 -> 0 | G34: =0 -> 0 | H34: =IF(D34<=0,0,IF(D34>=255,$C$3,INDEX($M$7:$M$23,MATCH(D34,$L$7:$L$23,1))+(D34-INDEX($L$7:$L$23,MATCH(D34,$L$7:$L$23,1)))*(INDEX($M$7:$M$23,MATCH(D34,$L$7:$L$23,1)+1)-INDEX($M$7:$M$23,MATCH(D34,$L$7:$L$23,1)))/(INDEX($L$7:$L$23,MATCH(D34,$L$7:$L$23,1)+1)-INDEX($L$7:$L$23,MATCH(D34,$L$7:$L$23,1))))) -> 31.789687 | I34: =H34-B34 -> 0.0646875 | J34: =IF(B34=0,0,ABS(I34/B34)) -> 0.0020390071 | K34: 扩展
A35: 28 | B35: =MIN(A35*$I$3,$C$3) -> 32.9 | C35: =IF(B35<=0,0,IF(B35>=$C$3,255,INDEX($L$7:$L$23,MATCH(B35,$M$7:$M$23,1))+(B35-INDEX($M$7:$M$23,MATCH(B35,$M$7:$M$23,1)))*(INDEX($L$7:$L$23,MATCH(B35,$M$7:$M$23,1)+1)-INDEX($L$7:$L$23,MATCH(B35,$M$7:$M$23,1)))/(INDEX($M$7:$M$23,MATCH(B35,$M$7:$M$23,1)+1)-INDEX($M$7:$M$23,MATCH(B35,$M$7:$M$23,1))))) -> 214.08861 | D35: =ROUND(C35,0) -> 214 | E35: =D35 -> 214 | F35: =0 -> 0 | G35: =0 -> 0 | H35: =IF(D35<=0,0,IF(D35>=255,$C$3,INDEX($M$7:$M$23,MATCH(D35,$L$7:$L$23,1))+(D35-INDEX($L$7:$L$23,MATCH(D35,$L$7:$L$23,1)))*(INDEX($M$7:$M$23,MATCH(D35,$L$7:$L$23,1)+1)-INDEX($M$7:$M$23,MATCH(D35,$L$7:$L$23,1)))/(INDEX($L$7:$L$23,MATCH(D35,$L$7:$L$23,1)+1)-INDEX($L$7:$L$23,MATCH(D35,$L$7:$L$23,1))))) -> 32.875937 | I35: =H35-B35 -> -0.0240625 | J35: =IF(B35=0,0,ABS(I35/B35)) -> 0.00073138298 | K35: 扩展
... A43: 36 | B43: =MIN(A43*$I$3,$C$3) -> 42.25 | C43: =IF(B43<=0,0,IF(B43>=$C$3,255,INDEX($L$7:$L$23,MATCH(B43,$M$7:$M$23,1))+(B43-INDEX($M$7:$M$23,MATCH(B43,$M$7:$M$23,1)))*(INDEX($L$7:$L$23,MATCH(B43,$M$7:$M$23,1)+1)-INDEX($L$7:$L$23,MATCH(B43,$M$7:$M$23,1)))/(INDEX($M$7:$M$23,MATCH(B43,$M$7:$M$23,1)+1)-INDEX($M$7:$M$23,MATCH(B43,$M$7:$M$23,1))))) -> 255 | D43: =ROUND(C43,0) -> 255 | E43: =D43 -> 255 | F43: =0 -> 0 | G43: =0 -> 0 | H43: =IF(D43<=0,0,IF(D43>=255,$C$3,INDEX($M$7:$M$23,MATCH(D43,$L$7:$L$23,1))+(D43-INDEX($L$7:$L$23,MATCH(D43,$L$7:$L$23,1)))*(INDEX($M$7:$M$23,MATCH(D43,$L$7:$L$23,1)+1)-INDEX($M$7:$M$23,MATCH(D43,$L$7:$L$23,1)))/(INDEX($L$7:$L$23,MATCH(D43,$L$7:$L$23,1)+1)-INDEX($L$7:$L$23,MATCH(D43,$L$7:$L$23,1))))) -> 42.25 | I43: =H43-B43 -> 0 | J43: =IF(B43=0,0,ABS(I43/B43)) -> 0 | K43: 扩展

Sheet G
A1: Green：0–127 扩展等亮度刺激标定
A2: 方法：0–20 级沿用现有标定；21 级以后继续以 1.175 cd/m² 为步长，用两次测量最终平均曲线做分段线性反插值。末级目标亮度截断为刺激值 255 的实测亮度。
A3: 255实测亮度 (cd/m²) | C3: 148.66667 | D3: 最大强度等级 | F3: 127 | G3: 标准亮度步长 (cd/m²) | I3: 1.175 | J3: 最大刺激值 | M3: 255
A4: 注意：等级 0 定义为 RGB=(0,0,0)，测量曲线中补入 (输入0, 亮度0)。原 0–20 级的目标亮度、连续反插值、推荐整数 RGB 和预计亮度保持不变；“扩展”行仅用于该通道高于 23.5 cd/m² 的范围。
A6: 强度等级 | B6: 目标亮度 (cd/m²) | C6: 反插值通道值 (连续) | D6: 推荐通道值 (整数) | E6: R | F6: G | G6: B | H6: 预计亮度 (cd/m²) | I6: 亮度误差 (cd/m²) | J6: 相对误差 | K6: 区段 | L6: 实测输入值 | M6: 最终平均亮度 (cd/m²)
A7: 0 | B7: =MIN(A7*$I$3,$C$3) -> 0 | C7: =IF(B7<=0,0,IF(B7>=$C$3,255,INDEX($L$7:$L$23,MATCH(B7,$M$7:$M$23,1))+(B7-INDEX($M$7:$M$23,MATCH(B7,$M$7:$M$23,1)))*(INDEX($L$7:$L$23,MATCH(B7,$M$7:$M$23,1)+1)-INDEX($L$7:$L$23,MATCH(B7,$M$7:$M$23,1)))/(INDEX($M$7:$M$23,MATCH(B7,$M$7:$M$23,1)+1)-INDEX($M$7:$M$23,MATCH(B7,$M$7:$M$23,1))))) -> 0 | D7: =ROUND(C7,0) -> 0 | E7: =0 -> 0 | F7: =D7 -> 0 | G7: =0 -> 0 | H7: =IF(D7<=0,0,IF(D7>=255,$C$3,INDEX($M$7:$M$23,MATCH(D7,$L$7:$L$23,1))+(D7-INDEX($L$7:$L$23,MATCH(D7,$L$7:$L$23,1)))*(INDEX($M$7:$M$23,MATCH(D7,$L$7:$L$23,1)+1)-INDEX($M$7:$M$23,MATCH(D7,$L$7:$L$23,1)))/(INDEX($L$7:$L$23,MATCH(D7,$L$7:$L$23,1)+1)-INDEX($L$7:$L$23,MATCH(D7,$L$7:$L$23,1))))) -> 0 | I7: =H7-B7 -> 0 | J7: =IF(B7=0,0,ABS(I7/B7)) -> 0 | K7: 原0–20 | L7: 0 | M7: 0
A8: 1 | B8: =MIN(A8*$I$3,$C$3) -> 1.175 | C8: =IF(B8<=0,0,IF(B8>=$C$3,255,INDEX($L$7:$L$23,MATCH(B8,$M$7:$M$23,1))+(B8-INDEX($M$7:$M$23,MATCH(B8,$M$7:$M$23,1)))*(INDEX($L$7:$L$23,MATCH(B8,$M$7:$M$23,1)+1)-INDEX($L$7:$L$23,MATCH(B8,$M$7:$M$23,1)))/(INDEX($M$7:$M$23,MATCH(B8,$M$7:$M$23,1)+1)-INDEX($M$7:$M$23,MATCH(B8,$M$7:$M$23,1))))) -> 19.703362 | D8: =ROUND(C8,0) -> 20 | E8: =0 -> 0 | F8: =D8 -> 20 | G8: =0 -> 0 | H8: =IF(D8<=0,0,IF(D8>=255,$C$3,INDEX($M$7:$M$23,MATCH(D8,$L$7:$L$23,1))+(D8-INDEX($L$7:$L$23,MATCH(D8,$L$7:$L$23,1)))*(INDEX($M$7:$M$23,MATCH(D8,$L$7:$L$23,1)+1)-INDEX($M$7:$M$23,MATCH(D8,$L$7:$L$23,1)))/(INDEX($L$7:$L$23,MATCH(D8,$L$7:$L$23,1)+1)-INDEX($L$7:$L$23,MATCH(D8,$L$7:$L$23,1))))) -> 1.2047646 | I8: =H8-B8 -> 0.029764583 | J8: =IF(B8=0,0,ABS(I8/B8)) -> 0.02533156 | K8: 原0–20 | L8: 15 | M8: 0.70306667
A9: 2 | B9: =MIN(A9*$I$3,$C$3) -> 2.35 | C9: =IF(B9<=0,0,IF(B9>=$C$3,255,INDEX($L$7:$L$23,MATCH(B9,$M$7:$M$23,1))+(B9-INDEX($M$7:$M$23,MATCH(B9,$M$7:$M$23,1)))*(INDEX($L$7:$L$23,MATCH(B9,$M$7:$M$23,1)+1)-INDEX($L$7:$L$23,MATCH(B9,$M$7:$M$23,1)))/(INDEX($M$7:$M$23,MATCH(B9,$M$7:$M$23,1)+1)-INDEX($M$7:$M$23,MATCH(B9,$M$7:$M$23,1))))) -> 31.219807 | D9: =ROUND(C9,0) -> 31 | E9: =0 -> 0 | F9: =D9 -> 31 | G9: =0 -> 0 | H9: =IF(D9<=0,0,IF(D9>=255,$C$3,INDEX($M$7:$M$23,MATCH(D9,$L$7:$L$23,1))+(D9-INDEX($L$7:$L$23,MATCH(D9,$L$7:$L$23,1)))*(INDEX($M$7:$M$23,MATCH(D9,$L$7:$L$23,1)+1)-INDEX($M$7:$M$23,MATCH(D9,$L$7:$L$23,1)))/(INDEX($L$7:$L$23,MATCH(D9,$L$7:$L$23,1)+1)-INDEX($L$7:$L$23,MATCH(D9,$L$7:$L$23,1))))) -> 2.3085 | I9: =H9-B9 -> -0.0415 | J9: =IF(B9=0,0,ABS(I9/B9)) -> 0.017659574 | K9: 原0–20 | L9: 31 | M9: 2.3085
A10: 3 | B10: =MIN(A10*$I$3,$C$3) -> 3.525 | C10: =IF(B10<=0,0,IF(B10>=$C$3,255,INDEX($L$7:$L$23,MATCH(B10,$M$7:$M$23,1))+(B10-INDEX($M$7:$M$23,MATCH(B10,$M$7:$M$23,1)))*(INDEX($L$7:$L$23,MATCH(B10,$M$7:$M$23,1)+1)-INDEX($L$7:$L$23,MATCH(B10,$M$7:$M$23,1)))/(INDEX($M$7:$M$23,MATCH(B10,$M$7:$M$23,1)+1)-INDEX($M$7:$M$23,MATCH(B10,$M$7:$M$23,1))))) -> 37.443255 | D10: =ROUND(C10,0) -> 37 | E10: =0 -> 0 | F10: =D10 -> 37 | G10: =0 -> 0 | H10: =IF(D10<=0,0,IF(D10>=255,$C$3,INDEX($M$7:$M$23,MATCH(D10,$L$7:$L$23,1))+(D10-INDEX($L$7:$L$23,MATCH(D10,$L$7:$L$23,1)))*(INDEX($M$7:$M$23,MATCH(D10,$L$7:$L$23,1)+1)-INDEX($M$7:$M$23,MATCH(D10,$L$7:$L$23,1)))/(INDEX($L$7:$L$23,MATCH(D10,$L$7:$L$23,1)+1)-INDEX($L$7:$L$23,MATCH(D10,$L$7:$L$23,1))))) -> 3.4413125 | I10: =H10-B10 -> -0.0836875 | J10: =IF(B10=0,0,ABS(I10/B10)) -> 0.023741135 | K10: 原0–20 | L10: 47 | M10: 5.3293333
A11: 4 | B11: =MIN(A11*$I$3,$C$3) -> 4.7 | C11: =IF(B11<=0,0,IF(B11>=$C$3,255,INDEX($L$7:$L$23,MATCH(B11,$M$7:$M$23,1))+(B11-INDEX($M$7:$M$23,MATCH(B11,$M$7:$M$23,1)))*(INDEX($L$7:$L$23,MATCH(B11,$M$7:$M$23,1)+1)-INDEX($L$7:$L$23,MATCH(B11,$M$7:$M$23,1)))/(INDEX($M$7:$M$23,MATCH(B11,$M$7:$M$23,1)+1)-INDEX($M$7:$M$23,MATCH(B11,$M$7:$M$23,1))))) -> 43.666703 | D11: =ROUND(C11,0) -> 44 | E11: =0 -> 0 | F11: =D11 -> 44 | G11: =0 -> 0 | H11: =IF(D11<=0,0,IF(D11>=255,$C$3,INDEX($M$7:$M$23,MATCH(D11,$L$7:$L$23,1))+(D11-INDEX($L$7:$L$23,MATCH(D11,$L$7:$L$23,1)))*(INDEX($M$7:$M$23,MATCH(D11,$L$7:$L$23,1)+1)-INDEX($M$7:$M$23,MATCH(D11,$L$7:$L$23,1)))/(INDEX($L$7:$L$23,MATCH(D11,$L$7:$L$23,1)+1)-INDEX($L$7:$L$23,MATCH(D11,$L$7:$L$23,1))))) -> 4.7629271 | I11: =H11-B11 -> 0.062927083 | J11: =IF(B11=0,0,ABS(I11/B11)) -> 0.013388741 | K11: 原0–20 | L11: 63 | M11: 9.0171667
A12: 5 | B12: =MIN(A12*$I$3,$C$3) -> 5.875 | C12: =IF(B12<=0,0,IF(B12>=$C$3,255,INDEX($L$7:$L$23,MATCH(B12,$M$7:$M$23,1))+(B12-INDEX($M$7:$M$23,MATCH(B12,$M$7:$M$23,1)))*(INDEX($L$7:$L$23,MATCH(B12,$M$7:$M$23,1)+1)-INDEX($L$7:$L$23,MATCH(B12,$M$7:$M$23,1)))/(INDEX($M$7:$M$23,MATCH(B12,$M$7:$M$23,1)+1)-INDEX($M$7:$M$23,MATCH(B12,$M$7:$M$23,1))))) -> 49.367424 | D12: =ROUND(C12,0) -> 49 | E12: =0 -> 0 | F12: =D12 -> 49 | G12: =0 -> 0 | H12: =IF(D12<=0,0,IF(D12>=255,$C$3,INDEX($M$7:$M$23,MATCH(D12,$L$7:$L$23,1))+(D12-INDEX($L$7:$L$23,MATCH(D12,$L$7:$L$23,1)))*(INDEX($M$7:$M$23,MATCH(D12,$L$7:$L$23,1)+1)-INDEX($M$7:$M$23,MATCH(D12,$L$7:$L$23,1)))/(INDEX($L$7:$L$23,MATCH(D12,$L$7:$L$23,1)+1)-INDEX($L$7:$L$23,MATCH(D12,$L$7:$L$23,1))))) -> 5.7903125 | I12: =H12-B12 -> -0.0846875 | J12: =IF(B12=0,0,ABS(I12/B12)) -> 0.014414894 | K12: 原0–20 | L12: 79 | M12: 15.061667
A13: 6 | B13: =MIN(A13*$I$3,$C$3) -> 7.05 | C13: =IF(B13<=0,0,IF(B13>=$C$3,255,INDEX($L$7:$L$23,MATCH(B13,$M$7:$M$23,1))+(B13-INDEX($M$7:$M$23,MATCH(B13,$M$7:$M$23,1)))*(INDEX($L$7:$L$23,MATCH(B13,$M$7:$M$23,1)+1)-INDEX($L$7:$L$23,MATCH(B13,$M$7:$M$23,1)))/(INDEX($M$7:$M$23,MATCH(B13,$M$7:$M$23,1)+1)-INDEX($M$7:$M$23,MATCH(B13,$M$7:$M$23,1))))) -> 54.465269 | D13: =ROUND(C13,0) -> 54 | E13: =0 -> 0 | F13: =D13 -> 54 | G13: =0 -> 0 | H13: =IF(D13<=0,0,IF(D13>=255,$C$3,INDEX($M$7:$M$23,MATCH(D13,$L$7:$L$23,1))+(D13-INDEX($L$7:$L$23,MATCH(D13,$L$7:$L$23,1)))*(INDEX($M$7:$M$23,MATCH(D13,$L$7:$L$23,1)+1)-INDEX($M$7:$M$23,MATCH(D13,$L$7:$L$23,1)))/(INDEX($L$7:$L$23,MATCH(D13,$L$7:$L$23,1)+1)-INDEX($L$7:$L$23,MATCH(D13,$L$7:$L$23,1))))) -> 6.9427604 | I13: =H13-B13 -> -0.10723958 | J13: =IF(B13=0,0,ABS(I13/B13)) -> 0.015211288 | K13: 原0–20 | L13: 95 | M13: 21.061667
A14: 7 | B14: =MIN(A14*$I$3,$C$3) -> 8.225 | C14: =IF(B14<=0,0,IF(B14>=$C$3,255,INDEX($L$7:$L$23,MATCH(B14,$M$7:$M$23,1))+(B14-INDEX($M$7:$M$23,MATCH(B14,$M$7:$M$23,1)))*(INDEX($L$7:$L$23,MATCH(B14,$M$7:$M$23,1)+1)-INDEX($L$7:$L$23,MATCH(B14,$M$7:$M$23,1)))/(INDEX($M$7:$M$23,MATCH(B14,$M$7:$M$23,1)+1)-INDEX($M$7:$M$23,MATCH(B14,$M$7:$M$23,1))))) -> 59.563113 | D14: =ROUND(C14,0) -> 60 | E14: =0 -> 0 | F14: =D14 -> 60 | G14: =0 -> 0 | H14: =IF(D14<=0,0,IF(D14>=255,$C$3,INDEX($M$7:$M$23,MATCH(D14,$L$7:$L$23,1))+(D14-INDEX($L$7:$L$23,MATCH(D14,$L$7:$L$23,1)))*(INDEX($M$7:$M$23,MATCH(D14,$L$7:$L$23,1)+1)-INDEX($M$7:$M$23,MATCH(D14,$L$7:$L$23,1)))/(INDEX($L$7:$L$23,MATCH(D14,$L$7:$L$23,1)+1)-INDEX($L$7:$L$23,MATCH(D14,$L$7:$L$23,1))))) -> 8.3256979 | I14: =H14-B14 -> 0.10069792 | J14: =IF(B14=0,0,ABS(I14/B14)) -> 0.012242908 | K14: 原0–20 | L14: 111 | M14: 29.376667
A15: 8 | B15: =MIN(A15*$I$3,$C$3) -> 9.4 | C15: =IF(B15<=0,0,IF(B15>=$C$3,255,INDEX($L$7:$L$23,MATCH(B15,$M$7:$M$23,1))+(B15-INDEX($M$7:$M$23,MATCH(B15,$M$7:$M$23,1)))*(INDEX($L$7:$L$23,MATCH(B15,$M$7:$M$23,1)+1)-INDEX($L$7:$L$23,MATCH(B15,$M$7:$M$23,1)))/(INDEX($M$7:$M$23,MATCH(B15,$M$7:$M$23,1)+1)-INDEX($M$7:$M$23,MATCH(B15,$M$7:$M$23,1))))) -> 64.013373 | D15: =ROUND(C15,0) -> 64 | E15: =0 -> 0 | F15: =D15 -> 64 | G15: =0 -> 0 | H15: =IF(D15<=0,0,IF(D15>=255,$C$3,INDEX($M$7:$M$23,MATCH(D15,$L$7:$L$23,1))+(D15-INDEX($L$7:$L$23,MATCH(D15,$L$7:$L$23,1)))*(INDEX($M$7:$M$23,MATCH(D15,$L$7:$L$23,1)+1)-INDEX($M$7:$M$23,MATCH(D15,$L$7:$L$23,1)))/(INDEX($L$7:$L$23,MATCH(D15,$L$7:$L$23,1)+1)-INDEX($L$7:$L$23,MATCH(D15,$L$7:$L$23,1))))) -> 9.3949479 | I15: =H15-B15 -> -0.0050520833 | J15: =IF(B15=0,0,ABS(I15/B15)) -> 0.00053745567 | K15: 原0–20 | L15: 127 | M15: 38.628333
A16: 9 | B16: =MIN(A16*$I$3,$C$3) -> 10.575 | C16: =IF(B16<=0,0,IF(B16>=$C$3,255,INDEX($L$7:$L$23,MATCH(B16,$M$7:$M$23,1))+(B16-INDEX($M$7:$M$23,MATCH(B16,$M$7:$M$23,1)))*(INDEX($L$7:$L$23,MATCH(B16,$M$7:$M$23,1)+1)-INDEX($L$7:$L$23,MATCH(B16,$M$7:$M$23,1)))/(INDEX($M$7:$M$23,MATCH(B16,$M$7:$M$23,1)+1)-INDEX($M$7:$M$23,MATCH(B16,$M$7:$M$23,1))))) -> 67.123639 | D16: =ROUND(C16,0) -> 67 | E16: =0 -> 0 | F16: =D16 -> 67 | G16: =0 -> 0 | H16: =IF(D16<=0,0,IF(D16>=255,$C$3,INDEX($M$7:$M$23,MATCH(D16,$L$7:$L$23,1))+(D16-INDEX($L$7:$L$23,MATCH(D16,$L$7:$L$23,1)))*(INDEX($M$7:$M$23,MATCH(D16,$L$7:$L$23,1)+1)-INDEX($M$7:$M$23,MATCH(D16,$L$7:$L$23,1)))/(INDEX($L$7:$L$23,MATCH(D16,$L$7:$L$23,1)+1)-INDEX($L$7:$L$23,MATCH(D16,$L$7:$L$23,1))))) -> 10.528292 | I16: =H16-B16 -> -0.046708333 | J16: =IF(B16=0,0,ABS(I16/B16)) -> 0.0044168637 | K16: 原0–20 | L16: 143 | M16: 49.806667
A17: 10 | B17: =MIN(A17*$I$3,$C$3) -> 11.75 | C17: =IF(B17<=0,0,IF(B17>=$C$3,255,INDEX($L$7:$L$23,MATCH(B17,$M$7:$M$23,1))+(B17-INDEX($M$7:$M$23,MATCH(B17,$M$7:$M$23,1)))*(INDEX($L$7:$L$23,MATCH(B17,$M$7:$M$23,1)+1)-INDEX($L$7:$L$23,MATCH(B17,$M$7:$M$23,1)))/(INDEX($M$7:$M$23,MATCH(B17,$M$7:$M$23,1)+1)-INDEX($M$7:$M$23,MATCH(B17,$M$7:$M$23,1))))) -> 70.233904 | D17: =ROUND(C17,0) -> 70 | E17: =0 -> 0 | F17: =D17 -> 70 | G17: =0 -> 0 | H17: =IF(D17<=0,0,IF(D17>=255,$C$3,INDEX($M$7:$M$23,MATCH(D17,$L$7:$L$23,1))+(D17-INDEX($L$7:$L$23,MATCH(D17,$L$7:$L$23,1)))*(INDEX($M$7:$M$23,MATCH(D17,$L$7:$L$23,1)+1)-INDEX($M$7:$M$23,MATCH(D17,$L$7:$L$23,1)))/(INDEX($L$7:$L$23,MATCH(D17,$L$7:$L$23,1)+1)-INDEX($L$7:$L$23,MATCH(D17,$L$7:$L$23,1))))) -> 11.661635 | I17: =H17-B17 -> -0.088364583 | J17: =IF(B17=0,0,ABS(I17/B17)) -> 0.0075203901 | K17: 原0–20 | L17: 159 | M17: 62.856667
A18: 11 | B18: =MIN(A18*$I$3,$C$3) -> 12.925 | C18: =IF(B18<=0,0,IF(B18>=$C$3,255,INDEX($L$7:$L$23,MATCH(B18,$M$7:$M$23,1))+(B18-INDEX($M$7:$M$23,MATCH(B18,$M$7:$M$23,1)))*(INDEX($L$7:$L$23,MATCH(B18,$M$7:$M$23,1)+1)-INDEX($L$7:$L$23,MATCH(B18,$M$7:$M$23,1)))/(INDEX($M$7:$M$23,MATCH(B18,$M$7:$M$23,1)+1)-INDEX($M$7:$M$23,MATCH(B18,$M$7:$M$23,1))))) -> 73.34417 | D18: =ROUND(C18,0) -> 73 | E18: =0 -> 0 | F18: =D18 -> 73 | G18: =0 -> 0 | H18: =IF(D18<=0,0,IF(D18>=255,$C$3,INDEX($M$7:$M$23,MATCH(D18,$L$7:$L$23,1))+(D18-INDEX($L$7:$L$23,MATCH(D18,$L$7:$L$23,1)))*(INDEX($M$7:$M$23,MATCH(D18,$L$7:$L$23,1)+1)-INDEX($M$7:$M$23,MATCH(D18,$L$7:$L$23,1)))/(INDEX($L$7:$L$23,MATCH(D18,$L$7:$L$23,1)+1)-INDEX($L$7:$L$23,MATCH(D18,$L$7:$L$23,1))))) -> 12.794979 | I18: =H18-B18 -> -0.13002083 | J18: =IF(B18=0,0,ABS(I18/B18)) -> 0.010059639 | K18: 原0–20 | L18: 175 | M18: 75.101667
... A23: 16 | B23: =MIN(A23*$I$3,$C$3) -> 18.8 | C23: =IF(B23<=0,0,IF(B23>=$C$3,255,INDEX($L$7:$L$23,MATCH(B23,$M$7:$M$23,1))+(B23-INDEX($M$7:$M$23,MATCH(B23,$M$7:$M$23,1)))*(INDEX($L$7:$L$23,MATCH(B23,$M$7:$M$23,1)+1)-INDEX($L$7:$L$23,MATCH(B23,$M$7:$M$23,1)))/(INDEX($M$7:$M$23,MATCH(B23,$M$7:$M$23,1)+1)-INDEX($M$7:$M$23,MATCH(B23,$M$7:$M$23,1))))) -> 88.968889 | D23: =ROUND(C23,0) -> 89 | E23: =0 -> 0 | F23: =D23 -> 89 | G23: =0 -> 0 | H23: =IF(D23<=0,0,IF(D23>=255,$C$3,INDEX($M$7:$M$23,MATCH(D23,$L$7:$L$23,1))+(D23-INDEX($L$7:$L$23,MATCH(D23,$L$7:$L$23,1)))*(INDEX($M$7:$M$23,MATCH(D23,$L$7:$L$23,1)+1)-INDEX($M$7:$M$23,MATCH(D23,$L$7:$L$23,1)))/(INDEX($L$7:$L$23,MATCH(D23,$L$7:$L$23,1)+1)-INDEX($L$7:$L$23,MATCH(D23,$L$7:$L$23,1))))) -> 18.811667 | I23: =H23-B23 -> 0.011666667 | J23: =IF(B23=0,0,ABS(I23/B23)) -> 0.00062056738 | K23: 原0–20 | L23: 255 | M23: 148.66667
A24: 17 | B24: =MIN(A24*$I$3,$C$3) -> 19.975 | C24: =IF(B24<=0,0,IF(B24>=$C$3,255,INDEX($L$7:$L$23,MATCH(B24,$M$7:$M$23,1))+(B24-INDEX($M$7:$M$23,MATCH(B24,$M$7:$M$23,1)))*(INDEX($L$7:$L$23,MATCH(B24,$M$7:$M$23,1)+1)-INDEX($L$7:$L$23,MATCH(B24,$M$7:$M$23,1)))/(INDEX($M$7:$M$23,MATCH(B24,$M$7:$M$23,1)+1)-INDEX($M$7:$M$23,MATCH(B24,$M$7:$M$23,1))))) -> 92.102222 | D24: =ROUND(C24,0) -> 92 | E24: =0 -> 0 | F24: =D24 -> 92 | G24: =0 -> 0 | H24: =IF(D24<=0,0,IF(D24>=255,$C$3,INDEX($M$7:$M$23,MATCH(D24,$L$7:$L$23,1))+(D24-INDEX($L$7:$L$23,MATCH(D24,$L$7:$L$23,1)))*(INDEX($M$7:$M$23,MATCH(D24,$L$7:$L$23,1)+1)-INDEX($M$7:$M$23,MATCH(D24,$L$7:$L$23,1)))/(INDEX($L$7:$L$23,MATCH(D24,$L$7:$L$23,1)+1)-INDEX($L$7:$L$23,MATCH(D24,$L$7:$L$23,1))))) -> 19.936667 | I24: =H24-B24 -> -0.038333333 | J24: =IF(B24=0,0,ABS(I24/B24)) -> 0.0019190655 | K24: 原0–20
A25: 18 | B25: =MIN(A25*$I$3,$C$3) -> 21.15 | C25: =IF(B25<=0,0,IF(B25>=$C$3,255,INDEX($L$7:$L$23,MATCH(B25,$M$7:$M$23,1))+(B25-INDEX($M$7:$M$23,MATCH(B25,$M$7:$M$23,1)))*(INDEX($L$7:$L$23,MATCH(B25,$M$7:$M$23,1)+1)-INDEX($L$7:$L$23,MATCH(B25,$M$7:$M$23,1)))/(INDEX($M$7:$M$23,MATCH(B25,$M$7:$M$23,1)+1)-INDEX($M$7:$M$23,MATCH(B25,$M$7:$M$23,1))))) -> 95.169974 | D25: =ROUND(C25,0) -> 95 | E25: =0 -> 0 | F25: =D25 -> 95 | G25: =0 -> 0 | H25: =IF(D25<=0,0,IF(D25>=255,$C$3,INDEX($M$7:$M$23,MATCH(D25,$L$7:$L$23,1))+(D25-INDEX($L$7:$L$23,MATCH(D25,$L$7:$L$23,1)))*(INDEX($M$7:$M$23,MATCH(D25,$L$7:$L$23,1)+1)-INDEX($M$7:$M$23,MATCH(D25,$L$7:$L$23,1)))/(INDEX($L$7:$L$23,MATCH(D25,$L$7:$L$23,1)+1)-INDEX($L$7:$L$23,MATCH(D25,$L$7:$L$23,1))))) -> 21.061667 | I25: =H25-B25 -> -0.088333333 | J25: =IF(B25=0,0,ABS(I25/B25)) -> 0.0041765169 | K25: 原0–20
A26: 19 | B26: =MIN(A26*$I$3,$C$3) -> 22.325 | C26: =IF(B26<=0,0,IF(B26>=$C$3,255,INDEX($L$7:$L$23,MATCH(B26,$M$7:$M$23,1))+(B26-INDEX($M$7:$M$23,MATCH(B26,$M$7:$M$23,1)))*(INDEX($L$7:$L$23,MATCH(B26,$M$7:$M$23,1)+1)-INDEX($L$7:$L$23,MATCH(B26,$M$7:$M$23,1)))/(INDEX($M$7:$M$23,MATCH(B26,$M$7:$M$23,1)+1)-INDEX($M$7:$M$23,MATCH(B26,$M$7:$M$23,1))))) -> 97.430948 | D26: =ROUND(C26,0) -> 97 | E26: =0 -> 0 | F26: =D26 -> 97 | G26: =0 -> 0 | H26: =IF(D26<=0,0,IF(D26>=255,$C$3,INDEX($M$7:$M$23,MATCH(D26,$L$7:$L$23,1))+(D26-INDEX($L$7:$L$23,MATCH(D26,$L$7:$L$23,1)))*(INDEX($M$7:$M$23,MATCH(D26,$L$7:$L$23,1)+1)-INDEX($M$7:$M$23,MATCH(D26,$L$7:$L$23,1)))/(INDEX($L$7:$L$23,MATCH(D26,$L$7:$L$23,1)+1)-INDEX($L$7:$L$23,MATCH(D26,$L$7:$L$23,1))))) -> 22.101042 | I26: =H26-B26 -> -0.22395833 | J26: =IF(B26=0,0,ABS(I26/B26)) -> 0.010031728 | K26: 原0–20
A27: 20 | B27: =MIN(A27*$I$3,$C$3) -> 23.5 | C27: =IF(B27<=0,0,IF(B27>=$C$3,255,INDEX($L$7:$L$23,MATCH(B27,$M$7:$M$23,1))+(B27-INDEX($M$7:$M$23,MATCH(B27,$M$7:$M$23,1)))*(INDEX($L$7:$L$23,MATCH(B27,$M$7:$M$23,1)+1)-INDEX($L$7:$L$23,MATCH(B27,$M$7:$M$23,1)))/(INDEX($M$7:$M$23,MATCH(B27,$M$7:$M$23,1)+1)-INDEX($M$7:$M$23,MATCH(B27,$M$7:$M$23,1))))) -> 99.691922 | D27: =ROUND(C27,0) -> 100 | E27: =0 -> 0 | F27: =D27 -> 100 | G27: =0 -> 0 | H27: =IF(D27<=0,0,IF(D27>=255,$C$3,INDEX($M$7:$M$23,MATCH(D27,$L$7:$L$23,1))+(D27-INDEX($L$7:$L$23,MATCH(D27,$L$7:$L$23,1)))*(INDEX($M$7:$M$23,MATCH(D27,$L$7:$L$23,1)+1)-INDEX($M$7:$M$23,MATCH(D27,$L$7:$L$23,1)))/(INDEX($L$7:$L$23,MATCH(D27,$L$7:$L$23,1)+1)-INDEX($L$7:$L$23,MATCH(D27,$L$7:$L$23,1))))) -> 23.660104 | I27: =H27-B27 -> 0.16010417 | J27: =IF(B27=0,0,ABS(I27/B27)) -> 0.0068129433 | K27: 原0–20
A28: 21 | B28: =MIN(A28*$I$3,$C$3) -> 24.675 | C28: =IF(B28<=0,0,IF(B28>=$C$3,255,INDEX($L$7:$L$23,MATCH(B28,$M$7:$M$23,1))+(B28-INDEX($M$7:$M$23,MATCH(B28,$M$7:$M$23,1)))*(INDEX($L$7:$L$23,MATCH(B28,$M$7:$M$23,1)+1)-INDEX($L$7:$L$23,MATCH(B28,$M$7:$M$23,1)))/(INDEX($M$7:$M$23,MATCH(B28,$M$7:$M$23,1)+1)-INDEX($M$7:$M$23,MATCH(B28,$M$7:$M$23,1))))) -> 101.9529 | D28: =ROUND(C28,0) -> 102 | E28: =0 -> 0 | F28: =D28 -> 102 | G28: =0 -> 0 | H28: =IF(D28<=0,0,IF(D28>=255,$C$3,INDEX($M$7:$M$23,MATCH(D28,$L$7:$L$23,1))+(D28-INDEX($L$7:$L$23,MATCH(D28,$L$7:$L$23,1)))*(INDEX($M$7:$M$23,MATCH(D28,$L$7:$L$23,1)+1)-INDEX($M$7:$M$23,MATCH(D28,$L$7:$L$23,1)))/(INDEX($L$7:$L$23,MATCH(D28,$L$7:$L$23,1)+1)-INDEX($L$7:$L$23,MATCH(D28,$L$7:$L$23,1))))) -> 24.699479 | I28: =H28-B28 -> 0.024479167 | J28: =IF(B28=0,0,ABS(I28/B28)) -> 0.00099206349 | K28: 扩展
A29: 22 | B29: =MIN(A29*$I$3,$C$3) -> 25.85 | C29: =IF(B29<=0,0,IF(B29>=$C$3,255,INDEX($L$7:$L$23,MATCH(B29,$M$7:$M$23,1))+(B29-INDEX($M$7:$M$23,MATCH(B29,$M$7:$M$23,1)))*(INDEX($L$7:$L$23,MATCH(B29,$M$7:$M$23,1)+1)-INDEX($L$7:$L$23,MATCH(B29,$M$7:$M$23,1)))/(INDEX($M$7:$M$23,MATCH(B29,$M$7:$M$23,1)+1)-INDEX($M$7:$M$23,MATCH(B29,$M$7:$M$23,1))))) -> 104.21387 | D29: =ROUND(C29,0) -> 104 | E29: =0 -> 0 | F29: =D29 -> 104 | G29: =0 -> 0 | H29: =IF(D29<=0,0,IF(D29>=255,$C$3,INDEX($M$7:$M$23,MATCH(D29,$L$7:$L$23,1))+(D29-INDEX($L$7:$L$23,MATCH(D29,$L$7:$L$23,1)))*(INDEX($M$7:$M$23,MATCH(D29,$L$7:$L$23,1)+1)-INDEX($M$7:$M$23,MATCH(D29,$L$7:$L$23,1)))/(INDEX($L$7:$L$23,MATCH(D29,$L$7:$L$23,1)+1)-INDEX($L$7:$L$23,MATCH(D29,$L$7:$L$23,1))))) -> 25.738854 | I29: =H29-B29 -> -0.11114583 | J29: =IF(B29=0,0,ABS(I29/B29)) -> 0.0042996454 | K29: 扩展
A30: 23 | B30: =MIN(A30*$I$3,$C$3) -> 27.025 | C30: =IF(B30<=0,0,IF(B30>=$C$3,255,INDEX($L$7:$L$23,MATCH(B30,$M$7:$M$23,1))+(B30-INDEX($M$7:$M$23,MATCH(B30,$M$7:$M$23,1)))*(INDEX($L$7:$L$23,MATCH(B30,$M$7:$M$23,1)+1)-INDEX($L$7:$L$23,MATCH(B30,$M$7:$M$23,1)))/(INDEX($M$7:$M$23,MATCH(B30,$M$7:$M$23,1)+1)-INDEX($M$7:$M$23,MATCH(B30,$M$7:$M$23,1))))) -> 106.47484 | D30: =ROUND(C30,0) -> 106 | E30: =0 -> 0 | F30: =D30 -> 106 | G30: =0 -> 0 | H30: =IF(D30<=0,0,IF(D30>=255,$C$3,INDEX($M$7:$M$23,MATCH(D30,$L$7:$L$23,1))+(D30-INDEX($L$7:$L$23,MATCH(D30,$L$7:$L$23,1)))*(INDEX($M$7:$M$23,MATCH(D30,$L$7:$L$23,1)+1)-INDEX($M$7:$M$23,MATCH(D30,$L$7:$L$23,1)))/(INDEX($L$7:$L$23,MATCH(D30,$L$7:$L$23,1)+1)-INDEX($L$7:$L$23,MATCH(D30,$L$7:$L$23,1))))) -> 26.778229 | I30: =H30-B30 -> -0.24677083 | J30: =IF(B30=0,0,ABS(I30/B30)) -> 0.0091312057 | K30: 扩展
A31: 24 | B31: =MIN(A31*$I$3,$C$3) -> 28.2 | C31: =IF(B31<=0,0,IF(B31>=$C$3,255,INDEX($L$7:$L$23,MATCH(B31,$M$7:$M$23,1))+(B31-INDEX($M$7:$M$23,MATCH(B31,$M$7:$M$23,1)))*(INDEX($L$7:$L$23,MATCH(B31,$M$7:$M$23,1)+1)-INDEX($L$7:$L$23,MATCH(B31,$M$7:$M$23,1)))/(INDEX($M$7:$M$23,MATCH(B31,$M$7:$M$23,1)+1)-INDEX($M$7:$M$23,MATCH(B31,$M$7:$M$23,1))))) -> 108.73582 | D31: =ROUND(C31,0) -> 109 | E31: =0 -> 0 | F31: =D31 -> 109 | G31: =0 -> 0 | H31: =IF(D31<=0,0,IF(D31>=255,$C$3,INDEX($M$7:$M$23,MATCH(D31,$L$7:$L$23,1))+(D31-INDEX($L$7:$L$23,MATCH(D31,$L$7:$L$23,1)))*(INDEX($M$7:$M$23,MATCH(D31,$L$7:$L$23,1)+1)-INDEX($M$7:$M$23,MATCH(D31,$L$7:$L$23,1)))/(INDEX($L$7:$L$23,MATCH(D31,$L$7:$L$23,1)+1)-INDEX($L$7:$L$23,MATCH(D31,$L$7:$L$23,1))))) -> 28.337292 | I31: =H31-B31 -> 0.13729167 | J31: =IF(B31=0,0,ABS(I31/B31)) -> 0.0048684988 | K31: 扩展
A32: 25 | B32: =MIN(A32*$I$3,$C$3) -> 29.375 | C32: =IF(B32<=0,0,IF(B32>=$C$3,255,INDEX($L$7:$L$23,MATCH(B32,$M$7:$M$23,1))+(B32-INDEX($M$7:$M$23,MATCH(B32,$M$7:$M$23,1)))*(INDEX($L$7:$L$23,MATCH(B32,$M$7:$M$23,1)+1)-INDEX($L$7:$L$23,MATCH(B32,$M$7:$M$23,1)))/(INDEX($M$7:$M$23,MATCH(B32,$M$7:$M$23,1)+1)-INDEX($M$7:$M$23,MATCH(B32,$M$7:$M$23,1))))) -> 110.99679 | D32: =ROUND(C32,0) -> 111 | E32: =0 -> 0 | F32: =D32 -> 111 | G32: =0 -> 0 | H32: =IF(D32<=0,0,IF(D32>=255,$C$3,INDEX($M$7:$M$23,MATCH(D32,$L$7:$L$23,1))+(D32-INDEX($L$7:$L$23,MATCH(D32,$L$7:$L$23,1)))*(INDEX($M$7:$M$23,MATCH(D32,$L$7:$L$23,1)+1)-INDEX($M$7:$M$23,MATCH(D32,$L$7:$L$23,1)))/(INDEX($L$7:$L$23,MATCH(D32,$L$7:$L$23,1)+1)-INDEX($L$7:$L$23,MATCH(D32,$L$7:$L$23,1))))) -> 29.376667 | I32: =H32-B32 -> 0.0016666667 | J32: =IF(B32=0,0,ABS(I32/B32)) -> 5.6737589e-05 | K32: 扩展
A33: 26 | B33: =MIN(A33*$I$3,$C$3) -> 30.55 | C33: =IF(B33<=0,0,IF(B33>=$C$3,255,INDEX($L$7:$L$23,MATCH(B33,$M$7:$M$23,1))+(B33-INDEX($M$7:$M$23,MATCH(B33,$M$7:$M$23,1)))*(INDEX($L$7:$L$23,MATCH(B33,$M$7:$M$23,1)+1)-INDEX($L$7:$L$23,MATCH(B33,$M$7:$M$23,1)))/(INDEX($M$7:$M$23,MATCH(B33,$M$7:$M$23,1)+1)-INDEX($M$7:$M$23,MATCH(B33,$M$7:$M$23,1))))) -> 113.02918 | D33: =ROUND(C33,0) -> 113 | E33: =0 -> 0 | F33: =D33 -> 113 | G33: =0 -> 0 | H33: =IF(D33<=0,0,IF(D33>=255,$C$3,INDEX($M$7:$M$23,MATCH(D33,$L$7:$L$23,1))+(D33-INDEX($L$7:$L$23,MATCH(D33,$L$7:$L$23,1)))*(INDEX($M$7:$M$23,MATCH(D33,$L$7:$L$23,1)+1)-INDEX($M$7:$M$23,MATCH(D33,$L$7:$L$23,1)))/(INDEX($L$7:$L$23,MATCH(D33,$L$7:$L$23,1)+1)-INDEX($L$7:$L$23,MATCH(D33,$L$7:$L$23,1))))) -> 30.533125 | I33: =H33-B33 -> -0.016875 | J33: =IF(B33=0,0,ABS(I33/B33)) -> 0.00055237316 | K33: 扩展
A34: 27 | B34: =MIN(A34*$I$3,$C$3) -> 31.725 | C34: =IF(B34<=0,0,IF(B34>=$C$3,255,INDEX($L$7:$L$23,MATCH(B34,$M$7:$M$23,1))+(B34-INDEX($M$7:$M$23,MATCH(B34,$M$7:$M$23,1)))*(INDEX($L$7:$L$23,MATCH(B34,$M$7:$M$23,1)+1)-INDEX($L$7:$L$23,MATCH(B34,$M$7:$M$23,1)))/(INDEX($M$7:$M$23,MATCH(B34,$M$7:$M$23,1)+1)-INDEX($M$7:$M$23,MATCH(B34,$M$7:$M$23,1))))) -> 115.06125 | D34: =ROUND(C34,0) -> 115 | E34: =0 -> 0 | F34: =D34 -> 115 | G34: =0 -> 0 | H34: =IF(D34<=0,0,IF(D34>=255,$C$3,INDEX($M$7:$M$23,MATCH(D34,$L$7:$L$23,1))+(D34-INDEX($L$7:$L$23,MATCH(D34,$L$7:$L$23,1)))*(INDEX($M$7:$M$23,MATCH(D34,$L$7:$L$23,1)+1)-INDEX($M$7:$M$23,MATCH(D34,$L$7:$L$23,1)))/(INDEX($L$7:$L$23,MATCH(D34,$L$7:$L$23,1)+1)-INDEX($L$7:$L$23,MATCH(D34,$L$7:$L$23,1))))) -> 31.689583 | I34: =H34-B34 -> -0.035416667 | J34: =IF(B34=0,0,ABS(I34/B34)) -> 0.0011163646 | K34: 扩展
A35: 28 | B35: =MIN(A35*$I$3,$C$3) -> 32.9 | C35: =IF(B35<=0,0,IF(B35>=$C$3,255,INDEX($L$7:$L$23,MATCH(B35,$M$7:$M$23,1))+(B35-INDEX($M$7:$M$23,MATCH(B35,$M$7:$M$23,1)))*(INDEX($L$7:$L$23,MATCH(B35,$M$7:$M$23,1)+1)-INDEX($L$7:$L$23,MATCH(B35,$M$7:$M$23,1)))/(INDEX($M$7:$M$23,MATCH(B35,$M$7:$M$23,1)+1)-INDEX($M$7:$M$23,MATCH(B35,$M$7:$M$23,1))))) -> 117.09332 | D35: =ROUND(C35,0) -> 117 | E35: =0 -> 0 | F35: =D35 -> 117 | G35: =0 -> 0 | H35: =IF(D35<=0,0,IF(D35>=255,$C$3,INDEX($M$7:$M$23,MATCH(D35,$L$7:$L$23,1))+(D35-INDEX($L$7:$L$23,MATCH(D35,$L$7:$L$23,1)))*(INDEX($M$7:$M$23,MATCH(D35,$L$7:$L$23,1)+1)-INDEX($M$7:$M$23,MATCH(D35,$L$7:$L$23,1)))/(INDEX($L$7:$L$23,MATCH(D35,$L$7:$L$23,1)+1)-INDEX($L$7:$L$23,MATCH(D35,$L$7:$L$23,1))))) -> 32.846042 | I35: =H35-B35 -> -0.053958333 | J35: =IF(B35=0,0,ABS(I35/B35)) -> 0.0016400709 | K35: 扩展
... A134: 127 | B134: =MIN(A134*$I$3,$C$3) -> 148.66667 | C134: =IF(B134<=0,0,IF(B134>=$C$3,255,INDEX($L$7:$L$23,MATCH(B134,$M$7:$M$23,1))+(B134-INDEX($M$7:$M$23,MATCH(B134,$M$7:$M$23,1)))*(INDEX($L$7:$L$23,MATCH(B134,$M$7:$M$23,1)+1)-INDEX($L$7:$L$23,MATCH(B134,$M$7:$M$23,1)))/(INDEX($M$7:$M$23,MATCH(B134,$M$7:$M$23,1)+1)-INDEX($M$7:$M$23,MATCH(B134,$M$7:$M$23,1))))) -> 255 | D134: =ROUND(C134,0) -> 255 | E134: =0 -> 0 | F134: =D134 -> 255 | G134: =0 -> 0 | H134: =IF(D134<=0,0,IF(D134>=255,$C$3,INDEX($M$7:$M$23,MATCH(D134,$L$7:$L$23,1))+(D134-INDEX($L$7:$L$23,MATCH(D134,$L$7:$L$23,1)))*(INDEX($M$7:$M$23,MATCH(D134,$L$7:$L$23,1)+1)-INDEX($M$7:$M$23,MATCH(D134,$L$7:$L$23,1)))/(INDEX($L$7:$L$23,MATCH(D134,$L$7:$L$23,1)+1)-INDEX($L$7:$L$23,MATCH(D134,$L$7:$L$23,1))))) -> 148.66667 | I134: =H134-B134 -> 0 | J134: =IF(B134=0,0,ABS(I134/B134)) -> 0 | K134: 扩展

Sheet B
A1: Blue：0–20 扩展等亮度刺激标定
A2: 方法：0–20 级沿用现有标定；21 级以后继续以 1.175 cd/m² 为步长，用两次测量最终平均曲线做分段线性反插值。末级目标亮度截断为刺激值 255 的实测亮度。
A3: 255实测亮度 (cd/m²) | C3: 23.5 | D3: 最大强度等级 | F3: 20 | G3: 标准亮度步长 (cd/m²) | I3: 1.175 | J3: 最大刺激值 | M3: 255
A4: 注意：等级 0 定义为 RGB=(0,0,0)，测量曲线中补入 (输入0, 亮度0)。原 0–20 级的目标亮度、连续反插值、推荐整数 RGB 和预计亮度保持不变；“扩展”行仅用于该通道高于 23.5 cd/m² 的范围。
A6: 强度等级 | B6: 目标亮度 (cd/m²) | C6: 反插值通道值 (连续) | D6: 推荐通道值 (整数) | E6: R | F6: G | G6: B | H6: 预计亮度 (cd/m²) | I6: 亮度误差 (cd/m²) | J6: 相对误差 | K6: 区段 | L6: 实测输入值 | M6: 最终平均亮度 (cd/m²)
A7: 0 | B7: =MIN(A7*$I$3,$C$3) -> 0 | C7: =IF(B7<=0,0,IF(B7>=$C$3,255,INDEX($L$7:$L$23,MATCH(B7,$M$7:$M$23,1))+(B7-INDEX($M$7:$M$23,MATCH(B7,$M$7:$M$23,1)))*(INDEX($L$7:$L$23,MATCH(B7,$M$7:$M$23,1)+1)-INDEX($L$7:$L$23,MATCH(B7,$M$7:$M$23,1)))/(INDEX($M$7:$M$23,MATCH(B7,$M$7:$M$23,1)+1)-INDEX($M$7:$M$23,MATCH(B7,$M$7:$M$23,1))))) -> 0 | D7: =ROUND(C7,0) -> 0 | E7: =0 -> 0 | F7: =0 -> 0 | G7: =D7 -> 0 | H7: =IF(D7<=0,0,IF(D7>=255,$C$3,INDEX($M$7:$M$23,MATCH(D7,$L$7:$L$23,1))+(D7-INDEX($L$7:$L$23,MATCH(D7,$L$7:$L$23,1)))*(INDEX($M$7:$M$23,MATCH(D7,$L$7:$L$23,1)+1)-INDEX($M$7:$M$23,MATCH(D7,$L$7:$L$23,1)))/(INDEX($L$7:$L$23,MATCH(D7,$L$7:$L$23,1)+1)-INDEX($L$7:$L$23,MATCH(D7,$L$7:$L$23,1))))) -> 0 | I7: =H7-B7 -> 0 | J7: =IF(B7=0,0,ABS(I7/B7)) -> 0 | K7: 原0–20 | L7: 0 | M7: 0
A8: 1 | B8: =MIN(A8*$I$3,$C$3) -> 1.175 | C8: =IF(B8<=0,0,IF(B8>=$C$3,255,INDEX($L$7:$L$23,MATCH(B8,$M$7:$M$23,1))+(B8-INDEX($M$7:$M$23,MATCH(B8,$M$7:$M$23,1)))*(INDEX($L$7:$L$23,MATCH(B8,$M$7:$M$23,1)+1)-INDEX($L$7:$L$23,MATCH(B8,$M$7:$M$23,1)))/(INDEX($M$7:$M$23,MATCH(B8,$M$7:$M$23,1)+1)-INDEX($M$7:$M$23,MATCH(B8,$M$7:$M$23,1))))) -> 57.844679 | D8: =ROUND(C8,0) -> 58 | E8: =0 -> 0 | F8: =0 -> 0 | G8: =D8 -> 58 | H8: =IF(D8<=0,0,IF(D8>=255,$C$3,INDEX($M$7:$M$23,MATCH(D8,$L$7:$L$23,1))+(D8-INDEX($L$7:$L$23,MATCH(D8,$L$7:$L$23,1)))*(INDEX($M$7:$M$23,MATCH(D8,$L$7:$L$23,1)+1)-INDEX($M$7:$M$23,MATCH(D8,$L$7:$L$23,1)))/(INDEX($L$7:$L$23,MATCH(D8,$L$7:$L$23,1)+1)-INDEX($L$7:$L$23,MATCH(D8,$L$7:$L$23,1))))) -> 1.1798958 | I8: =H8-B8 -> 0.0048958333 | J8: =IF(B8=0,0,ABS(I8/B8)) -> 0.0041666667 | K8: 原0–20 | L8: 15 | M8: 0.27046667
A9: 2 | B9: =MIN(A9*$I$3,$C$3) -> 2.35 | C9: =IF(B9<=0,0,IF(B9>=$C$3,255,INDEX($L$7:$L$23,MATCH(B9,$M$7:$M$23,1))+(B9-INDEX($M$7:$M$23,MATCH(B9,$M$7:$M$23,1)))*(INDEX($L$7:$L$23,MATCH(B9,$M$7:$M$23,1)+1)-INDEX($L$7:$L$23,MATCH(B9,$M$7:$M$23,1)))/(INDEX($M$7:$M$23,MATCH(B9,$M$7:$M$23,1)+1)-INDEX($M$7:$M$23,MATCH(B9,$M$7:$M$23,1))))) -> 84.600663 | D9: =ROUND(C9,0) -> 85 | E9: =0 -> 0 | F9: =0 -> 0 | G9: =D9 -> 85 | H9: =IF(D9<=0,0,IF(D9>=255,$C$3,INDEX($M$7:$M$23,MATCH(D9,$L$7:$L$23,1))+(D9-INDEX($L$7:$L$23,MATCH(D9,$L$7:$L$23,1)))*(INDEX($M$7:$M$23,MATCH(D9,$L$7:$L$23,1)+1)-INDEX($M$7:$M$23,MATCH(D9,$L$7:$L$23,1)))/(INDEX($L$7:$L$23,MATCH(D9,$L$7:$L$23,1)+1)-INDEX($L$7:$L$23,MATCH(D9,$L$7:$L$23,1))))) -> 2.3700833 | I9: =H9-B9 -> 0.020083333 | J9: =IF(B9=0,0,ABS(I9/B9)) -> 0.0085460993 | K9: 原0–20 | L9: 31 | M9: 0.45925
A10: 3 | B10: =MIN(A10*$I$3,$C$3) -> 3.525 | C10: =IF(B10<=0,0,IF(B10>=$C$3,255,INDEX($L$7:$L$23,MATCH(B10,$M$7:$M$23,1))+(B10-INDEX($M$7:$M$23,MATCH(B10,$M$7:$M$23,1)))*(INDEX($L$7:$L$23,MATCH(B10,$M$7:$M$23,1)+1)-INDEX($L$7:$L$23,MATCH(B10,$M$7:$M$23,1)))/(INDEX($M$7:$M$23,MATCH(B10,$M$7:$M$23,1)+1)-INDEX($M$7:$M$23,MATCH(B10,$M$7:$M$23,1))))) -> 104.07788 | D10: =ROUND(C10,0) -> 104 | E10: =0 -> 0 | F10: =0 -> 0 | G10: =D10 -> 104 | H10: =IF(D10<=0,0,IF(D10>=255,$C$3,INDEX($M$7:$M$23,MATCH(D10,$L$7:$L$23,1))+(D10-INDEX($L$7:$L$23,MATCH(D10,$L$7:$L$23,1)))*(INDEX($M$7:$M$23,MATCH(D10,$L$7:$L$23,1)+1)-INDEX($M$7:$M$23,MATCH(D10,$L$7:$L$23,1)))/(INDEX($L$7:$L$23,MATCH(D10,$L$7:$L$23,1)+1)-INDEX($L$7:$L$23,MATCH(D10,$L$7:$L$23,1))))) -> 3.5194063 | I10: =H10-B10 -> -0.00559375 | J10: =IF(B10=0,0,ABS(I10/B10)) -> 0.0015868794 | K10: 原0–20 | L10: 47 | M10: 0.83316667
A11: 4 | B11: =MIN(A11*$I$3,$C$3) -> 4.7 | C11: =IF(B11<=0,0,IF(B11>=$C$3,255,INDEX($L$7:$L$23,MATCH(B11,$M$7:$M$23,1))+(B11-INDEX($M$7:$M$23,MATCH(B11,$M$7:$M$23,1)))*(INDEX($L$7:$L$23,MATCH(B11,$M$7:$M$23,1)+1)-INDEX($L$7:$L$23,MATCH(B11,$M$7:$M$23,1)))/(INDEX($M$7:$M$23,MATCH(B11,$M$7:$M$23,1)+1)-INDEX($M$7:$M$23,MATCH(B11,$M$7:$M$23,1))))) -> 118.77908 | D11: =ROUND(C11,0) -> 119 | E11: =0 -> 0 | F11: =0 -> 0 | G11: =D11 -> 119 | H11: =IF(D11<=0,0,IF(D11>=255,$C$3,INDEX($M$7:$M$23,MATCH(D11,$L$7:$L$23,1))+(D11-INDEX($L$7:$L$23,MATCH(D11,$L$7:$L$23,1)))*(INDEX($M$7:$M$23,MATCH(D11,$L$7:$L$23,1)+1)-INDEX($M$7:$M$23,MATCH(D11,$L$7:$L$23,1)))/(INDEX($L$7:$L$23,MATCH(D11,$L$7:$L$23,1)+1)-INDEX($L$7:$L$23,MATCH(D11,$L$7:$L$23,1))))) -> 4.71925 | I11: =H11-B11 -> 0.01925 | J11: =IF(B11=0,0,ABS(I11/B11)) -> 0.0040957447 | K11: 原0–20 | L11: 63 | M11: 1.3375
A12: 5 | B12: =MIN(A12*$I$3,$C$3) -> 5.875 | C12: =IF(B12<=0,0,IF(B12>=$C$3,255,INDEX($L$7:$L$23,MATCH(B12,$M$7:$M$23,1))+(B12-INDEX($M$7:$M$23,MATCH(B12,$M$7:$M$23,1)))*(INDEX($L$7:$L$23,MATCH(B12,$M$7:$M$23,1)+1)-INDEX($L$7:$L$23,MATCH(B12,$M$7:$M$23,1)))/(INDEX($M$7:$M$23,MATCH(B12,$M$7:$M$23,1)+1)-INDEX($M$7:$M$23,MATCH(B12,$M$7:$M$23,1))))) -> 134.23497 | D12: =ROUND(C12,0) -> 134 | E12: =0 -> 0 | F12: =0 -> 0 | G12: =D12 -> 134 | H12: =IF(D12<=0,0,IF(D12>=255,$C$3,INDEX($M$7:$M$23,MATCH(D12,$L$7:$L$23,1))+(D12-INDEX($L$7:$L$23,MATCH(D12,$L$7:$L$23,1)))*(INDEX($M$7:$M$23,MATCH(D12,$L$7:$L$23,1)+1)-INDEX($M$7:$M$23,MATCH(D12,$L$7:$L$23,1)))/(INDEX($L$7:$L$23,MATCH(D12,$L$7:$L$23,1)+1)-INDEX($L$7:$L$23,MATCH(D12,$L$7:$L$23,1))))) -> 5.8601042 | I12: =H12-B12 -> -0.014895833 | J12: =IF(B12=0,0,ABS(I12/B12)) -> 0.002535461 | K12: 原0–20 | L12: 79 | M12: 2.0683333
A13: 6 | B13: =MIN(A13*$I$3,$C$3) -> 7.05 | C13: =IF(B13<=0,0,IF(B13>=$C$3,255,INDEX($L$7:$L$23,MATCH(B13,$M$7:$M$23,1))+(B13-INDEX($M$7:$M$23,MATCH(B13,$M$7:$M$23,1)))*(INDEX($L$7:$L$23,MATCH(B13,$M$7:$M$23,1)+1)-INDEX($L$7:$L$23,MATCH(B13,$M$7:$M$23,1)))/(INDEX($M$7:$M$23,MATCH(B13,$M$7:$M$23,1)+1)-INDEX($M$7:$M$23,MATCH(B13,$M$7:$M$23,1))))) -> 148.06009 | D13: =ROUND(C13,0) -> 148 | E13: =0 -> 0 | F13: =0 -> 0 | G13: =D13 -> 148 | H13: =IF(D13<=0,0,IF(D13>=255,$C$3,INDEX($M$7:$M$23,MATCH(D13,$L$7:$L$23,1))+(D13-INDEX($L$7:$L$23,MATCH(D13,$L$7:$L$23,1)))*(INDEX($M$7:$M$23,MATCH(D13,$L$7:$L$23,1)+1)-INDEX($M$7:$M$23,MATCH(D13,$L$7:$L$23,1)))/(INDEX($L$7:$L$23,MATCH(D13,$L$7:$L$23,1)+1)-INDEX($L$7:$L$23,MATCH(D13,$L$7:$L$23,1))))) -> 7.0426458 | I13: =H13-B13 -> -0.0073541667 | J13: =IF(B13=0,0,ABS(I13/B13)) -> 0.0010431442 | K13: 原0–20 | L13: 95 | M13: 2.873
A14: 7 | B14: =MIN(A14*$I$3,$C$3) -> 8.225 | C14: =IF(B14<=0,0,IF(B14>=$C$3,255,INDEX($L$7:$L$23,MATCH(B14,$M$7:$M$23,1))+(B14-INDEX($M$7:$M$23,MATCH(B14,$M$7:$M$23,1)))*(INDEX($L$7:$L$23,MATCH(B14,$M$7:$M$23,1)+1)-INDEX($L$7:$L$23,MATCH(B14,$M$7:$M$23,1)))/(INDEX($M$7:$M$23,MATCH(B14,$M$7:$M$23,1)+1)-INDEX($M$7:$M$23,MATCH(B14,$M$7:$M$23,1))))) -> 157.66009 | D14: =ROUND(C14,0) -> 158 | E14: =0 -> 0 | F14: =0 -> 0 | G14: =D14 -> 158 | H14: =IF(D14<=0,0,IF(D14>=255,$C$3,INDEX($M$7:$M$23,MATCH(D14,$L$7:$L$23,1))+(D14-INDEX($L$7:$L$23,MATCH(D14,$L$7:$L$23,1)))*(INDEX($M$7:$M$23,MATCH(D14,$L$7:$L$23,1)+1)-INDEX($M$7:$M$23,MATCH(D14,$L$7:$L$23,1)))/(INDEX($L$7:$L$23,MATCH(D14,$L$7:$L$23,1)+1)-INDEX($L$7:$L$23,MATCH(D14,$L$7:$L$23,1))))) -> 8.2666042 | I14: =H14-B14 -> 0.041604167 | J14: =IF(B14=0,0,ABS(I14/B14)) -> 0.0050582573 | K14: 原0–20 | L14: 111 | M14: 4.0221667
A15: 8 | B15: =MIN(A15*$I$3,$C$3) -> 9.4 | C15: =IF(B15<=0,0,IF(B15>=$C$3,255,INDEX($L$7:$L$23,MATCH(B15,$M$7:$M$23,1))+(B15-INDEX($M$7:$M$23,MATCH(B15,$M$7:$M$23,1)))*(INDEX($L$7:$L$23,MATCH(B15,$M$7:$M$23,1)+1)-INDEX($L$7:$L$23,MATCH(B15,$M$7:$M$23,1)))/(INDEX($M$7:$M$23,MATCH(B15,$M$7:$M$23,1)+1)-INDEX($M$7:$M$23,MATCH(B15,$M$7:$M$23,1))))) -> 168.96059 | D15: =ROUND(C15,0) -> 169 | E15: =0 -> 0 | F15: =0 -> 0 | G15: =D15 -> 169 | H15: =IF(D15<=0,0,IF(D15>=255,$C$3,INDEX($M$7:$M$23,MATCH(D15,$L$7:$L$23,1))+(D15-INDEX($L$7:$L$23,MATCH(D15,$L$7:$L$23,1)))*(INDEX($M$7:$M$23,MATCH(D15,$L$7:$L$23,1)+1)-INDEX($M$7:$M$23,MATCH(D15,$L$7:$L$23,1)))/(INDEX($L$7:$L$23,MATCH(D15,$L$7:$L$23,1)+1)-INDEX($L$7:$L$23,MATCH(D15,$L$7:$L$23,1))))) -> 9.404 | I15: =H15-B15 -> 0.004 | J15: =IF(B15=0,0,ABS(I15/B15)) -> 0.00042553191 | K15: 原0–20 | L15: 127 | M15: 5.4163333
A16: 9 | B16: =MIN(A16*$I$3,$C$3) -> 10.575 | C16: =IF(B16<=0,0,IF(B16>=$C$3,255,INDEX($L$7:$L$23,MATCH(B16,$M$7:$M$23,1))+(B16-INDEX($M$7:$M$23,MATCH(B16,$M$7:$M$23,1)))*(INDEX($L$7:$L$23,MATCH(B16,$M$7:$M$23,1)+1)-INDEX($L$7:$L$23,MATCH(B16,$M$7:$M$23,1)))/(INDEX($M$7:$M$23,MATCH(B16,$M$7:$M$23,1)+1)-INDEX($M$7:$M$23,MATCH(B16,$M$7:$M$23,1))))) -> 180.63056 | D16: =ROUND(C16,0) -> 181 | E16: =0 -> 0 | F16: =0 -> 0 | G16: =D16 -> 181 | H16: =IF(D16<=0,0,IF(D16>=255,$C$3,INDEX($M$7:$M$23,MATCH(D16,$L$7:$L$23,1))+(D16-INDEX($L$7:$L$23,MATCH(D16,$L$7:$L$23,1)))*(INDEX($M$7:$M$23,MATCH(D16,$L$7:$L$23,1)+1)-INDEX($M$7:$M$23,MATCH(D16,$L$7:$L$23,1)))/(INDEX($L$7:$L$23,MATCH(D16,$L$7:$L$23,1)+1)-INDEX($L$7:$L$23,MATCH(D16,$L$7:$L$23,1))))) -> 10.611875 | I16: =H16-B16 -> 0.036875 | J16: =IF(B16=0,0,ABS(I16/B16)) -> 0.0034869976 | K16: 原0–20 | L16: 143 | M16: 6.4306667
A17: 10 | B17: =MIN(A17*$I$3,$C$3) -> 11.75 | C17: =IF(B17<=0,0,IF(B17>=$C$3,255,INDEX($L$7:$L$23,MATCH(B17,$M$7:$M$23,1))+(B17-INDEX($M$7:$M$23,MATCH(B17,$M$7:$M$23,1)))*(INDEX($L$7:$L$23,MATCH(B17,$M$7:$M$23,1)+1)-INDEX($L$7:$L$23,MATCH(B17,$M$7:$M$23,1)))/(INDEX($M$7:$M$23,MATCH(B17,$M$7:$M$23,1)+1)-INDEX($M$7:$M$23,MATCH(B17,$M$7:$M$23,1))))) -> 191.8281 | D17: =ROUND(C17,0) -> 192 | E17: =0 -> 0 | F17: =0 -> 0 | G17: =D17 -> 192 | H17: =IF(D17<=0,0,IF(D17>=255,$C$3,INDEX($M$7:$M$23,MATCH(D17,$L$7:$L$23,1))+(D17-INDEX($L$7:$L$23,MATCH(D17,$L$7:$L$23,1)))*(INDEX($M$7:$M$23,MATCH(D17,$L$7:$L$23,1)+1)-INDEX($M$7:$M$23,MATCH(D17,$L$7:$L$23,1)))/(INDEX($L$7:$L$23,MATCH(D17,$L$7:$L$23,1)+1)-INDEX($L$7:$L$23,MATCH(D17,$L$7:$L$23,1))))) -> 11.779063 | I17: =H17-B17 -> 0.0290625 | J17: =IF(B17=0,0,ABS(I17/B17)) -> 0.0024734043 | K17: 原0–20 | L17: 159 | M17: 8.389
A18: 11 | B18: =MIN(A18*$I$3,$C$3) -> 12.925 | C18: =IF(B18<=0,0,IF(B18>=$C$3,255,INDEX($L$7:$L$23,MATCH(B18,$M$7:$M$23,1))+(B18-INDEX($M$7:$M$23,MATCH(B18,$M$7:$M$23,1)))*(INDEX($L$7:$L$23,MATCH(B18,$M$7:$M$23,1)+1)-INDEX($L$7:$L$23,MATCH(B18,$M$7:$M$23,1)))/(INDEX($M$7:$M$23,MATCH(B18,$M$7:$M$23,1)+1)-INDEX($M$7:$M$23,MATCH(B18,$M$7:$M$23,1))))) -> 198.77819 | D18: =ROUND(C18,0) -> 199 | E18: =0 -> 0 | F18: =0 -> 0 | G18: =D18 -> 199 | H18: =IF(D18<=0,0,IF(D18>=255,$C$3,INDEX($M$7:$M$23,MATCH(D18,$L$7:$L$23,1))+(D18-INDEX($L$7:$L$23,MATCH(D18,$L$7:$L$23,1)))*(INDEX($M$7:$M$23,MATCH(D18,$L$7:$L$23,1)+1)-INDEX($M$7:$M$23,MATCH(D18,$L$7:$L$23,1)))/(INDEX($L$7:$L$23,MATCH(D18,$L$7:$L$23,1)+1)-INDEX($L$7:$L$23,MATCH(D18,$L$7:$L$23,1))))) -> 12.9625 | I18: =H18-B18 -> 0.0375 | J18: =IF(B18=0,0,ABS(I18/B18)) -> 0.002901354 | K18: 原0–20 | L18: 175 | M18: 10.013
... A23: 16 | B23: =MIN(A23*$I$3,$C$3) -> 18.8 | C23: =IF(B23<=0,0,IF(B23>=$C$3,255,INDEX($L$7:$L$23,MATCH(B23,$M$7:$M$23,1))+(B23-INDEX($M$7:$M$23,MATCH(B23,$M$7:$M$23,1)))*(INDEX($L$7:$L$23,MATCH(B23,$M$7:$M$23,1)+1)-INDEX($L$7:$L$23,MATCH(B23,$M$7:$M$23,1)))/(INDEX($M$7:$M$23,MATCH(B23,$M$7:$M$23,1)+1)-INDEX($M$7:$M$23,MATCH(B23,$M$7:$M$23,1))))) -> 238.98577 | D23: =ROUND(C23,0) -> 239 | E23: =0 -> 0 | F23: =0 -> 0 | G23: =D23 -> 239 | H23: =IF(D23<=0,0,IF(D23>=255,$C$3,INDEX($M$7:$M$23,MATCH(D23,$L$7:$L$23,1))+(D23-INDEX($L$7:$L$23,MATCH(D23,$L$7:$L$23,1)))*(INDEX($M$7:$M$23,MATCH(D23,$L$7:$L$23,1)+1)-INDEX($M$7:$M$23,MATCH(D23,$L$7:$L$23,1)))/(INDEX($L$7:$L$23,MATCH(D23,$L$7:$L$23,1)+1)-INDEX($L$7:$L$23,MATCH(D23,$L$7:$L$23,1))))) -> 18.801667 | I23: =H23-B23 -> 0.0016666667 | J23: =IF(B23=0,0,ABS(I23/B23)) -> 8.8652482e-05 | K23: 原0–20 | L23: 255 | M23: 23.5
A24: 17 | B24: =MIN(A24*$I$3,$C$3) -> 19.975 | C24: =IF(B24<=0,0,IF(B24>=$C$3,255,INDEX($L$7:$L$23,MATCH(B24,$M$7:$M$23,1))+(B24-INDEX($M$7:$M$23,MATCH(B24,$M$7:$M$23,1)))*(INDEX($L$7:$L$23,MATCH(B24,$M$7:$M$23,1)+1)-INDEX($L$7:$L$23,MATCH(B24,$M$7:$M$23,1)))/(INDEX($M$7:$M$23,MATCH(B24,$M$7:$M$23,1)+1)-INDEX($M$7:$M$23,MATCH(B24,$M$7:$M$23,1))))) -> 242.99574 | D24: =ROUND(C24,0) -> 243 | E24: =0 -> 0 | F24: =0 -> 0 | G24: =D24 -> 243 | H24: =IF(D24<=0,0,IF(D24>=255,$C$3,INDEX($M$7:$M$23,MATCH(D24,$L$7:$L$23,1))+(D24-INDEX($L$7:$L$23,MATCH(D24,$L$7:$L$23,1)))*(INDEX($M$7:$M$23,MATCH(D24,$L$7:$L$23,1)+1)-INDEX($M$7:$M$23,MATCH(D24,$L$7:$L$23,1)))/(INDEX($L$7:$L$23,MATCH(D24,$L$7:$L$23,1)+1)-INDEX($L$7:$L$23,MATCH(D24,$L$7:$L$23,1))))) -> 19.97625 | I24: =H24-B24 -> 0.00125 | J24: =IF(B24=0,0,ABS(I24/B24)) -> 6.2578223e-05 | K24: 原0–20
